Task terminal.tasks.clean_expired_session_period[ef63b16e-fe49-42ed-bf02-0ab8565d593f] raised unexpected: OperationalError(1054, "Unknown column 'terminal_session.org_id' in 'field list'")
Traceback (most recent call last):
  File "/opt/py3/lib/python3.6/site-packages/django/db/backends/utils.py", line 85, in _execute
    return self.cursor.execute(sql, params)
  File "/opt/py3/lib/python3.6/site-packages/django/db/backends/mysql/base.py", line 71, in execute
    return self.cursor.execute(query, args)
  File "/opt/py3/lib/python3.6/site-packages/MySQLdb/cursors.py", line 255, in execute
    self.errorhandler(self, exc, value)
  File "/opt/py3/lib/python3.6/site-packages/MySQLdb/connections.py", line 50, in defaulterrorhandler
    raise errorvalue
  File "/opt/py3/lib/python3.6/site-packages/MySQLdb/cursors.py", line 252, in execute
    res = self._query(query)
  File "/opt/py3/lib/python3.6/site-packages/MySQLdb/cursors.py", line 378, in _query
    db.query(q)
  File "/opt/py3/lib/python3.6/site-packages/MySQLdb/connections.py", line 280, in query
    _mysql.connection.query(self, query)
_mysql_exceptions.OperationalError: (1054, "Unknown column 'terminal_session.org_id' in 'field list'")

The above exception was the direct cause of the following exception:

Traceback (most recent call last):
  File "/opt/py3/lib/python3.6/site-packages/celery/app/trace.py", line 374, in trace_task
    R = retval = fun(*args, **kwargs)
  File "/opt/py3/lib/python3.6/site-packages/celery/app/trace.py", line 629, in __protected_call__
    return self.run(*args, **kwargs)
  File "/opt/jumpserver/apps/ops/celery/decorator.py", line 81, in wrapper
    return func(*args, **kwargs)
  File "/opt/jumpserver/apps/ops/celery/decorator.py", line 95, in decorate
    return func(*args, **kwargs)
  File "/opt/jumpserver/apps/ops/celery/decorator.py", line 108, in decorate
    return func(*args, **kwargs)
  File "/opt/jumpserver/apps/terminal/tasks.py", line 56, in clean_expired_session_period
    for session in expired_sessions:
  File "/opt/py3/lib/python3.6/site-packages/django/db/models/query.py", line 268, in __iter__
    self._fetch_all()
  File "/opt/py3/lib/python3.6/site-packages/django/db/models/query.py", line 1186, in _fetch_all
    self._result_cache = list(self._iterable_class(self))
  File "/opt/py3/lib/python3.6/site-packages/django/db/models/query.py", line 54, in __iter__
    results = compiler.execute_sql(chunked_fetch=self.chunked_fetch, chunk_size=self.chunk_size)
  File "/opt/py3/lib/python3.6/site-packages/django/db/models/sql/compiler.py", line 1065, in execute_sql
    cursor.execute(sql, params)
  File "/opt/py3/lib/python3.6/site-packages/django/db/backends/utils.py", line 68, in execute
    return self._execute_with_wrappers(sql, params, many=False, executor=self._execute)
  File "/opt/py3/lib/python3.6/site-packages/django/db/backends/utils.py", line 77, in _execute_with_wrappers
    return executor(sql, params, many, context)
  File "/opt/py3/lib/python3.6/site-packages/django/db/backends/utils.py", line 85, in _execute
    return self.cursor.execute(sql, params)
  File "/opt/py3/lib/python3.6/site-packages/django/db/utils.py", line 89, in __exit__
    raise dj_exc_value.with_traceback(traceback) from exc_value
  File "/opt/py3/lib/python3.6/site-packages/django/db/backends/utils.py", line 85, in _execute
    return self.cursor.execute(sql, params)
  File "/opt/py3/lib/python3.6/site-packages/django/db/backends/mysql/base.py", line 71, in execute
    return self.cursor.execute(query, args)
  File "/opt/py3/lib/python3.6/site-packages/MySQLdb/cursors.py", line 255, in execute
    self.errorhandler(self, exc, value)
  File "/opt/py3/lib/python3.6/site-packages/MySQLdb/connections.py", line 50, in defaulterrorhandler
    raise errorvalue
  File "/opt/py3/lib/python3.6/site-packages/MySQLdb/cursors.py", line 252, in execute
    res = self._query(query)
  File "/opt/py3/lib/python3.6/site-packages/MySQLdb/cursors.py", line 378, in _query
    db.query(q)
  File "/opt/py3/lib/python3.6/site-packages/MySQLdb/connections.py", line 280, in query
    _mysql.connection.query(self, query)
django.db.utils.OperationalError: (1054, "Unknown column 'terminal_session.org_id' in 'field list'")
