2019-02-18 18:23:18 [tasks ERROR] Sending mail error: [Errno -2] Name or service not known
2019-02-20 09:42:27 [log ERROR] Internal Server Error: /ops/command-execution/start/
Traceback (most recent call last):
  File "/opt/py3/lib/python3.6/site-packages/django/core/handlers/exception.py", line 34, in inner
    response = get_response(request)
  File "/opt/py3/lib/python3.6/site-packages/django/core/handlers/base.py", line 126, in _get_response
    response = self.process_exception_by_middleware(e, request)
  File "/opt/py3/lib/python3.6/site-packages/django/core/handlers/base.py", line 124, in _get_response
    response = wrapped_callback(request, *callback_args, **callback_kwargs)
  File "/usr/local/lib/python3.6/contextlib.py", line 53, in inner
    return func(*args, **kwds)
  File "/opt/py3/lib/python3.6/site-packages/django/views/generic/base.py", line 68, in view
    return self.dispatch(request, *args, **kwargs)
  File "/opt/py3/lib/python3.6/site-packages/django/views/generic/base.py", line 88, in dispatch
    return handler(request, *args, **kwargs)
  File "/opt/py3/lib/python3.6/site-packages/django/views/generic/base.py", line 149, in get
    context = self.get_context_data(**kwargs)
  File "/opt/jumpserver/apps/ops/views/command.py", line 65, in get_context_data
    system_users = self.get_user_system_users()
  File "/opt/jumpserver/apps/ops/views/command.py", line 61, in get_user_system_users
    system_users = [s for s in util.get_system_users() if s.protocol == 'ssh']
  File "/opt/jumpserver/apps/perms/utils.py", line 171, in get_system_users
    permissions = self.permissions.prefetch_related('system_users')
  File "/opt/jumpserver/apps/perms/utils.py", line 109, in permissions
    func = self.get_permissions_map[object_cls]
KeyError: 'AnonymousUser'
2019-02-20 19:35:55 [log ERROR] Internal Server Error: /api/perms/v1/user/nodes-assets/tree/
Traceback (most recent call last):
  File "/opt/py3/lib/python3.6/site-packages/django/db/models/fields/__init__.py", line 2325, in to_python
    return uuid.UUID(value)
  File "/usr/local/lib/python3.6/uuid.py", line 140, in __init__
    raise ValueError('badly formed hexadecimal UUID string')
ValueError: badly formed hexadecimal UUID string

During handling of the above exception, another exception occurred:

Traceback (most recent call last):
  File "/opt/py3/lib/python3.6/site-packages/django/core/handlers/exception.py", line 34, in inner
    response = get_response(request)
  File "/opt/py3/lib/python3.6/site-packages/django/core/handlers/base.py", line 126, in _get_response
    response = self.process_exception_by_middleware(e, request)
  File "/opt/py3/lib/python3.6/site-packages/django/core/handlers/base.py", line 124, in _get_response
    response = wrapped_callback(request, *callback_args, **callback_kwargs)
  File "/usr/local/lib/python3.6/contextlib.py", line 53, in inner
    return func(*args, **kwds)
  File "/opt/py3/lib/python3.6/site-packages/django/views/decorators/csrf.py", line 54, in wrapped_view
    return view_func(*args, **kwargs)
  File "/opt/py3/lib/python3.6/site-packages/django/views/generic/base.py", line 68, in view
    return self.dispatch(request, *args, **kwargs)
  File "/opt/py3/lib/python3.6/site-packages/rest_framework/views.py", line 483, in dispatch
    response = self.handle_exception(exc)
  File "/opt/py3/lib/python3.6/site-packages/rest_framework/views.py", line 443, in handle_exception
    self.raise_uncaught_exception(exc)
  File "/opt/py3/lib/python3.6/site-packages/rest_framework/views.py", line 480, in dispatch
    response = handler(request, *args, **kwargs)
  File "/opt/jumpserver/apps/perms/api.py", line 299, in get
    return super().get(request, *args, **kwargs)
  File "/opt/py3/lib/python3.6/site-packages/rest_framework/generics.py", line 201, in get
    return self.list(request, *args, **kwargs)
  File "/opt/py3/lib/python3.6/site-packages/rest_framework/mixins.py", line 40, in list
    queryset = self.filter_queryset(self.get_queryset())
  File "/opt/jumpserver/apps/perms/api.py", line 382, in get_queryset
    nodes = util.get_nodes_with_assets()
  File "/opt/jumpserver/apps/perms/utils.py", line 163, in get_nodes_with_assets
    assets = self.get_assets()
  File "/opt/jumpserver/apps/perms/utils.py", line 146, in get_assets
    assets = self.get_assets_direct()
  File "/opt/jumpserver/apps/perms/utils.py", line 135, in get_assets_direct
    permissions = self.permissions.prefetch_related('assets', 'system_users')
  File "/opt/jumpserver/apps/perms/utils.py", line 106, in permissions
    if self._permissions:
  File "/opt/py3/lib/python3.6/site-packages/django/db/models/query.py", line 272, in __bool__
    self._fetch_all()
  File "/opt/py3/lib/python3.6/site-packages/django/db/models/query.py", line 1186, in _fetch_all
    self._result_cache = list(self._iterable_class(self))
  File "/opt/py3/lib/python3.6/site-packages/django/db/models/query.py", line 54, in __iter__
    results = compiler.execute_sql(chunked_fetch=self.chunked_fetch, chunk_size=self.chunk_size)
  File "/opt/py3/lib/python3.6/site-packages/django/db/models/sql/compiler.py", line 1052, in execute_sql
    sql, params = self.as_sql()
  File "/opt/py3/lib/python3.6/site-packages/django/db/models/sql/compiler.py", line 464, in as_sql
    where, w_params = self.compile(self.where) if self.where is not None else ("", [])
  File "/opt/py3/lib/python3.6/site-packages/django/db/models/sql/compiler.py", line 390, in compile
    sql, params = node.as_sql(self, self.connection)
  File "/opt/py3/lib/python3.6/site-packages/django/db/models/sql/where.py", line 81, in as_sql
    sql, params = compiler.compile(child)
  File "/opt/py3/lib/python3.6/site-packages/django/db/models/sql/compiler.py", line 390, in compile
    sql, params = node.as_sql(self, self.connection)
  File "/opt/py3/lib/python3.6/site-packages/django/db/models/fields/related_lookups.py", line 130, in as_sql
    return super().as_sql(compiler, connection)
  File "/opt/py3/lib/python3.6/site-packages/django/db/models/lookups.py", line 163, in as_sql
    rhs_sql, rhs_params = self.process_rhs(compiler, connection)
  File "/opt/py3/lib/python3.6/site-packages/django/db/models/lookups.py", line 260, in process_rhs
    return super().process_rhs(compiler, connection)
  File "/opt/py3/lib/python3.6/site-packages/django/db/models/lookups.py", line 95, in process_rhs
    return self.get_db_prep_lookup(value, connection)
  File "/opt/py3/lib/python3.6/site-packages/django/db/models/lookups.py", line 187, in get_db_prep_lookup
    [get_db_prep_value(value, connection, prepared=True)]
  File "/opt/py3/lib/python3.6/site-packages/django/db/models/fields/related.py", line 940, in get_db_prep_value
    return self.target_field.get_db_prep_value(value, connection, prepared)
  File "/opt/py3/lib/python3.6/site-packages/django/db/models/fields/__init__.py", line 2316, in get_db_prep_value
    value = self.to_python(value)
  File "/opt/py3/lib/python3.6/site-packages/django/db/models/fields/__init__.py", line 2330, in to_python
    params={'value': value},
django.core.exceptions.ValidationError: ['‘qq’不是有效UUID。']
2019-02-20 19:47:37 [log ERROR] Internal Server Error: /api/perms/v1/user/nodes-assets/tree/
Traceback (most recent call last):
  File "/opt/py3/lib/python3.6/site-packages/django/db/models/fields/__init__.py", line 2325, in to_python
    return uuid.UUID(value)
  File "/usr/local/lib/python3.6/uuid.py", line 140, in __init__
    raise ValueError('badly formed hexadecimal UUID string')
ValueError: badly formed hexadecimal UUID string

During handling of the above exception, another exception occurred:

Traceback (most recent call last):
  File "/opt/py3/lib/python3.6/site-packages/django/core/handlers/exception.py", line 34, in inner
    response = get_response(request)
  File "/opt/py3/lib/python3.6/site-packages/django/core/handlers/base.py", line 126, in _get_response
    response = self.process_exception_by_middleware(e, request)
  File "/opt/py3/lib/python3.6/site-packages/django/core/handlers/base.py", line 124, in _get_response
    response = wrapped_callback(request, *callback_args, **callback_kwargs)
  File "/usr/local/lib/python3.6/contextlib.py", line 53, in inner
    return func(*args, **kwds)
  File "/opt/py3/lib/python3.6/site-packages/django/views/decorators/csrf.py", line 54, in wrapped_view
    return view_func(*args, **kwargs)
  File "/opt/py3/lib/python3.6/site-packages/django/views/generic/base.py", line 68, in view
    return self.dispatch(request, *args, **kwargs)
  File "/opt/py3/lib/python3.6/site-packages/rest_framework/views.py", line 483, in dispatch
    response = self.handle_exception(exc)
  File "/opt/py3/lib/python3.6/site-packages/rest_framework/views.py", line 443, in handle_exception
    self.raise_uncaught_exception(exc)
  File "/opt/py3/lib/python3.6/site-packages/rest_framework/views.py", line 480, in dispatch
    response = handler(request, *args, **kwargs)
  File "/opt/jumpserver/apps/perms/api.py", line 299, in get
    return super().get(request, *args, **kwargs)
  File "/opt/py3/lib/python3.6/site-packages/rest_framework/generics.py", line 201, in get
    return self.list(request, *args, **kwargs)
  File "/opt/py3/lib/python3.6/site-packages/rest_framework/mixins.py", line 40, in list
    queryset = self.filter_queryset(self.get_queryset())
  File "/opt/jumpserver/apps/perms/api.py", line 382, in get_queryset
    nodes = util.get_nodes_with_assets()
  File "/opt/jumpserver/apps/perms/utils.py", line 163, in get_nodes_with_assets
    assets = self.get_assets()
  File "/opt/jumpserver/apps/perms/utils.py", line 146, in get_assets
    assets = self.get_assets_direct()
  File "/opt/jumpserver/apps/perms/utils.py", line 135, in get_assets_direct
    permissions = self.permissions.prefetch_related('assets', 'system_users')
  File "/opt/jumpserver/apps/perms/utils.py", line 106, in permissions
    if self._permissions:
  File "/opt/py3/lib/python3.6/site-packages/django/db/models/query.py", line 272, in __bool__
    self._fetch_all()
  File "/opt/py3/lib/python3.6/site-packages/django/db/models/query.py", line 1186, in _fetch_all
    self._result_cache = list(self._iterable_class(self))
  File "/opt/py3/lib/python3.6/site-packages/django/db/models/query.py", line 54, in __iter__
    results = compiler.execute_sql(chunked_fetch=self.chunked_fetch, chunk_size=self.chunk_size)
  File "/opt/py3/lib/python3.6/site-packages/django/db/models/sql/compiler.py", line 1052, in execute_sql
    sql, params = self.as_sql()
  File "/opt/py3/lib/python3.6/site-packages/django/db/models/sql/compiler.py", line 464, in as_sql
    where, w_params = self.compile(self.where) if self.where is not None else ("", [])
  File "/opt/py3/lib/python3.6/site-packages/django/db/models/sql/compiler.py", line 390, in compile
    sql, params = node.as_sql(self, self.connection)
  File "/opt/py3/lib/python3.6/site-packages/django/db/models/sql/where.py", line 81, in as_sql
    sql, params = compiler.compile(child)
  File "/opt/py3/lib/python3.6/site-packages/django/db/models/sql/compiler.py", line 390, in compile
    sql, params = node.as_sql(self, self.connection)
  File "/opt/py3/lib/python3.6/site-packages/django/db/models/fields/related_lookups.py", line 130, in as_sql
    return super().as_sql(compiler, connection)
  File "/opt/py3/lib/python3.6/site-packages/django/db/models/lookups.py", line 163, in as_sql
    rhs_sql, rhs_params = self.process_rhs(compiler, connection)
  File "/opt/py3/lib/python3.6/site-packages/django/db/models/lookups.py", line 260, in process_rhs
    return super().process_rhs(compiler, connection)
  File "/opt/py3/lib/python3.6/site-packages/django/db/models/lookups.py", line 95, in process_rhs
    return self.get_db_prep_lookup(value, connection)
  File "/opt/py3/lib/python3.6/site-packages/django/db/models/lookups.py", line 187, in get_db_prep_lookup
    [get_db_prep_value(value, connection, prepared=True)]
  File "/opt/py3/lib/python3.6/site-packages/django/db/models/fields/related.py", line 940, in get_db_prep_value
    return self.target_field.get_db_prep_value(value, connection, prepared)
  File "/opt/py3/lib/python3.6/site-packages/django/db/models/fields/__init__.py", line 2316, in get_db_prep_value
    value = self.to_python(value)
  File "/opt/py3/lib/python3.6/site-packages/django/db/models/fields/__init__.py", line 2330, in to_python
    params={'value': value},
django.core.exceptions.ValidationError: ['‘ww’不是有效UUID。']
2019-02-20 19:47:39 [log ERROR] Internal Server Error: /api/perms/v1/user/nodes-assets/tree/
Traceback (most recent call last):
  File "/opt/py3/lib/python3.6/site-packages/django/db/models/fields/__init__.py", line 2325, in to_python
    return uuid.UUID(value)
  File "/usr/local/lib/python3.6/uuid.py", line 140, in __init__
    raise ValueError('badly formed hexadecimal UUID string')
ValueError: badly formed hexadecimal UUID string

During handling of the above exception, another exception occurred:

Traceback (most recent call last):
  File "/opt/py3/lib/python3.6/site-packages/django/core/handlers/exception.py", line 34, in inner
    response = get_response(request)
  File "/opt/py3/lib/python3.6/site-packages/django/core/handlers/base.py", line 126, in _get_response
    response = self.process_exception_by_middleware(e, request)
  File "/opt/py3/lib/python3.6/site-packages/django/core/handlers/base.py", line 124, in _get_response
    response = wrapped_callback(request, *callback_args, **callback_kwargs)
  File "/usr/local/lib/python3.6/contextlib.py", line 53, in inner
    return func(*args, **kwds)
  File "/opt/py3/lib/python3.6/site-packages/django/views/decorators/csrf.py", line 54, in wrapped_view
    return view_func(*args, **kwargs)
  File "/opt/py3/lib/python3.6/site-packages/django/views/generic/base.py", line 68, in view
    return self.dispatch(request, *args, **kwargs)
  File "/opt/py3/lib/python3.6/site-packages/rest_framework/views.py", line 483, in dispatch
    response = self.handle_exception(exc)
  File "/opt/py3/lib/python3.6/site-packages/rest_framework/views.py", line 443, in handle_exception
    self.raise_uncaught_exception(exc)
  File "/opt/py3/lib/python3.6/site-packages/rest_framework/views.py", line 480, in dispatch
    response = handler(request, *args, **kwargs)
  File "/opt/jumpserver/apps/perms/api.py", line 299, in get
    return super().get(request, *args, **kwargs)
  File "/opt/py3/lib/python3.6/site-packages/rest_framework/generics.py", line 201, in get
    return self.list(request, *args, **kwargs)
  File "/opt/py3/lib/python3.6/site-packages/rest_framework/mixins.py", line 40, in list
    queryset = self.filter_queryset(self.get_queryset())
  File "/opt/jumpserver/apps/perms/api.py", line 382, in get_queryset
    nodes = util.get_nodes_with_assets()
  File "/opt/jumpserver/apps/perms/utils.py", line 163, in get_nodes_with_assets
    assets = self.get_assets()
  File "/opt/jumpserver/apps/perms/utils.py", line 146, in get_assets
    assets = self.get_assets_direct()
  File "/opt/jumpserver/apps/perms/utils.py", line 135, in get_assets_direct
    permissions = self.permissions.prefetch_related('assets', 'system_users')
  File "/opt/jumpserver/apps/perms/utils.py", line 106, in permissions
    if self._permissions:
  File "/opt/py3/lib/python3.6/site-packages/django/db/models/query.py", line 272, in __bool__
    self._fetch_all()
  File "/opt/py3/lib/python3.6/site-packages/django/db/models/query.py", line 1186, in _fetch_all
    self._result_cache = list(self._iterable_class(self))
  File "/opt/py3/lib/python3.6/site-packages/django/db/models/query.py", line 54, in __iter__
    results = compiler.execute_sql(chunked_fetch=self.chunked_fetch, chunk_size=self.chunk_size)
  File "/opt/py3/lib/python3.6/site-packages/django/db/models/sql/compiler.py", line 1052, in execute_sql
    sql, params = self.as_sql()
  File "/opt/py3/lib/python3.6/site-packages/django/db/models/sql/compiler.py", line 464, in as_sql
    where, w_params = self.compile(self.where) if self.where is not None else ("", [])
  File "/opt/py3/lib/python3.6/site-packages/django/db/models/sql/compiler.py", line 390, in compile
    sql, params = node.as_sql(self, self.connection)
  File "/opt/py3/lib/python3.6/site-packages/django/db/models/sql/where.py", line 81, in as_sql
    sql, params = compiler.compile(child)
  File "/opt/py3/lib/python3.6/site-packages/django/db/models/sql/compiler.py", line 390, in compile
    sql, params = node.as_sql(self, self.connection)
  File "/opt/py3/lib/python3.6/site-packages/django/db/models/fields/related_lookups.py", line 130, in as_sql
    return super().as_sql(compiler, connection)
  File "/opt/py3/lib/python3.6/site-packages/django/db/models/lookups.py", line 163, in as_sql
    rhs_sql, rhs_params = self.process_rhs(compiler, connection)
  File "/opt/py3/lib/python3.6/site-packages/django/db/models/lookups.py", line 260, in process_rhs
    return super().process_rhs(compiler, connection)
  File "/opt/py3/lib/python3.6/site-packages/django/db/models/lookups.py", line 95, in process_rhs
    return self.get_db_prep_lookup(value, connection)
  File "/opt/py3/lib/python3.6/site-packages/django/db/models/lookups.py", line 187, in get_db_prep_lookup
    [get_db_prep_value(value, connection, prepared=True)]
  File "/opt/py3/lib/python3.6/site-packages/django/db/models/fields/related.py", line 940, in get_db_prep_value
    return self.target_field.get_db_prep_value(value, connection, prepared)
  File "/opt/py3/lib/python3.6/site-packages/django/db/models/fields/__init__.py", line 2316, in get_db_prep_value
    value = self.to_python(value)
  File "/opt/py3/lib/python3.6/site-packages/django/db/models/fields/__init__.py", line 2330, in to_python
    params={'value': value},
django.core.exceptions.ValidationError: ['‘qq’不是有效UUID。']
2019-02-20 19:47:40 [log ERROR] Internal Server Error: /api/perms/v1/user/nodes-assets/tree/
Traceback (most recent call last):
  File "/opt/py3/lib/python3.6/site-packages/django/db/models/fields/__init__.py", line 2325, in to_python
    return uuid.UUID(value)
  File "/usr/local/lib/python3.6/uuid.py", line 140, in __init__
    raise ValueError('badly formed hexadecimal UUID string')
ValueError: badly formed hexadecimal UUID string

During handling of the above exception, another exception occurred:

Traceback (most recent call last):
  File "/opt/py3/lib/python3.6/site-packages/django/core/handlers/exception.py", line 34, in inner
    response = get_response(request)
  File "/opt/py3/lib/python3.6/site-packages/django/core/handlers/base.py", line 126, in _get_response
    response = self.process_exception_by_middleware(e, request)
  File "/opt/py3/lib/python3.6/site-packages/django/core/handlers/base.py", line 124, in _get_response
    response = wrapped_callback(request, *callback_args, **callback_kwargs)
  File "/usr/local/lib/python3.6/contextlib.py", line 53, in inner
    return func(*args, **kwds)
  File "/opt/py3/lib/python3.6/site-packages/django/views/decorators/csrf.py", line 54, in wrapped_view
    return view_func(*args, **kwargs)
  File "/opt/py3/lib/python3.6/site-packages/django/views/generic/base.py", line 68, in view
    return self.dispatch(request, *args, **kwargs)
  File "/opt/py3/lib/python3.6/site-packages/rest_framework/views.py", line 483, in dispatch
    response = self.handle_exception(exc)
  File "/opt/py3/lib/python3.6/site-packages/rest_framework/views.py", line 443, in handle_exception
    self.raise_uncaught_exception(exc)
  File "/opt/py3/lib/python3.6/site-packages/rest_framework/views.py", line 480, in dispatch
    response = handler(request, *args, **kwargs)
  File "/opt/jumpserver/apps/perms/api.py", line 299, in get
    return super().get(request, *args, **kwargs)
  File "/opt/py3/lib/python3.6/site-packages/rest_framework/generics.py", line 201, in get
    return self.list(request, *args, **kwargs)
  File "/opt/py3/lib/python3.6/site-packages/rest_framework/mixins.py", line 40, in list
    queryset = self.filter_queryset(self.get_queryset())
  File "/opt/jumpserver/apps/perms/api.py", line 382, in get_queryset
    nodes = util.get_nodes_with_assets()
  File "/opt/jumpserver/apps/perms/utils.py", line 163, in get_nodes_with_assets
    assets = self.get_assets()
  File "/opt/jumpserver/apps/perms/utils.py", line 146, in get_assets
    assets = self.get_assets_direct()
  File "/opt/jumpserver/apps/perms/utils.py", line 135, in get_assets_direct
    permissions = self.permissions.prefetch_related('assets', 'system_users')
  File "/opt/jumpserver/apps/perms/utils.py", line 106, in permissions
    if self._permissions:
  File "/opt/py3/lib/python3.6/site-packages/django/db/models/query.py", line 272, in __bool__
    self._fetch_all()
  File "/opt/py3/lib/python3.6/site-packages/django/db/models/query.py", line 1186, in _fetch_all
    self._result_cache = list(self._iterable_class(self))
  File "/opt/py3/lib/python3.6/site-packages/django/db/models/query.py", line 54, in __iter__
    results = compiler.execute_sql(chunked_fetch=self.chunked_fetch, chunk_size=self.chunk_size)
  File "/opt/py3/lib/python3.6/site-packages/django/db/models/sql/compiler.py", line 1052, in execute_sql
    sql, params = self.as_sql()
  File "/opt/py3/lib/python3.6/site-packages/django/db/models/sql/compiler.py", line 464, in as_sql
    where, w_params = self.compile(self.where) if self.where is not None else ("", [])
  File "/opt/py3/lib/python3.6/site-packages/django/db/models/sql/compiler.py", line 390, in compile
    sql, params = node.as_sql(self, self.connection)
  File "/opt/py3/lib/python3.6/site-packages/django/db/models/sql/where.py", line 81, in as_sql
    sql, params = compiler.compile(child)
  File "/opt/py3/lib/python3.6/site-packages/django/db/models/sql/compiler.py", line 390, in compile
    sql, params = node.as_sql(self, self.connection)
  File "/opt/py3/lib/python3.6/site-packages/django/db/models/fields/related_lookups.py", line 130, in as_sql
    return super().as_sql(compiler, connection)
  File "/opt/py3/lib/python3.6/site-packages/django/db/models/lookups.py", line 163, in as_sql
    rhs_sql, rhs_params = self.process_rhs(compiler, connection)
  File "/opt/py3/lib/python3.6/site-packages/django/db/models/lookups.py", line 260, in process_rhs
    return super().process_rhs(compiler, connection)
  File "/opt/py3/lib/python3.6/site-packages/django/db/models/lookups.py", line 95, in process_rhs
    return self.get_db_prep_lookup(value, connection)
  File "/opt/py3/lib/python3.6/site-packages/django/db/models/lookups.py", line 187, in get_db_prep_lookup
    [get_db_prep_value(value, connection, prepared=True)]
  File "/opt/py3/lib/python3.6/site-packages/django/db/models/fields/related.py", line 940, in get_db_prep_value
    return self.target_field.get_db_prep_value(value, connection, prepared)
  File "/opt/py3/lib/python3.6/site-packages/django/db/models/fields/__init__.py", line 2316, in get_db_prep_value
    value = self.to_python(value)
  File "/opt/py3/lib/python3.6/site-packages/django/db/models/fields/__init__.py", line 2330, in to_python
    params={'value': value},
django.core.exceptions.ValidationError: ['‘ww’不是有效UUID。']
2019-02-21 09:34:31 [log ERROR] Internal Server Error: /api/perms/v1/user/nodes-assets/tree/
Traceback (most recent call last):
  File "/opt/py3/lib/python3.6/site-packages/django/db/models/fields/__init__.py", line 2325, in to_python
    return uuid.UUID(value)
  File "/usr/local/lib/python3.6/uuid.py", line 140, in __init__
    raise ValueError('badly formed hexadecimal UUID string')
ValueError: badly formed hexadecimal UUID string

During handling of the above exception, another exception occurred:

Traceback (most recent call last):
  File "/opt/py3/lib/python3.6/site-packages/django/core/handlers/exception.py", line 34, in inner
    response = get_response(request)
  File "/opt/py3/lib/python3.6/site-packages/django/core/handlers/base.py", line 126, in _get_response
    response = self.process_exception_by_middleware(e, request)
  File "/opt/py3/lib/python3.6/site-packages/django/core/handlers/base.py", line 124, in _get_response
    response = wrapped_callback(request, *callback_args, **callback_kwargs)
  File "/usr/local/lib/python3.6/contextlib.py", line 53, in inner
    return func(*args, **kwds)
  File "/opt/py3/lib/python3.6/site-packages/django/views/decorators/csrf.py", line 54, in wrapped_view
    return view_func(*args, **kwargs)
  File "/opt/py3/lib/python3.6/site-packages/django/views/generic/base.py", line 68, in view
    return self.dispatch(request, *args, **kwargs)
  File "/opt/py3/lib/python3.6/site-packages/rest_framework/views.py", line 483, in dispatch
    response = self.handle_exception(exc)
  File "/opt/py3/lib/python3.6/site-packages/rest_framework/views.py", line 443, in handle_exception
    self.raise_uncaught_exception(exc)
  File "/opt/py3/lib/python3.6/site-packages/rest_framework/views.py", line 480, in dispatch
    response = handler(request, *args, **kwargs)
  File "/opt/jumpserver/apps/perms/api.py", line 299, in get
    return super().get(request, *args, **kwargs)
  File "/opt/py3/lib/python3.6/site-packages/rest_framework/generics.py", line 201, in get
    return self.list(request, *args, **kwargs)
  File "/opt/py3/lib/python3.6/site-packages/rest_framework/mixins.py", line 40, in list
    queryset = self.filter_queryset(self.get_queryset())
  File "/opt/jumpserver/apps/perms/api.py", line 382, in get_queryset
    nodes = util.get_nodes_with_assets()
  File "/opt/jumpserver/apps/perms/utils.py", line 163, in get_nodes_with_assets
    assets = self.get_assets()
  File "/opt/jumpserver/apps/perms/utils.py", line 146, in get_assets
    assets = self.get_assets_direct()
  File "/opt/jumpserver/apps/perms/utils.py", line 135, in get_assets_direct
    permissions = self.permissions.prefetch_related('assets', 'system_users')
  File "/opt/jumpserver/apps/perms/utils.py", line 106, in permissions
    if self._permissions:
  File "/opt/py3/lib/python3.6/site-packages/django/db/models/query.py", line 272, in __bool__
    self._fetch_all()
  File "/opt/py3/lib/python3.6/site-packages/django/db/models/query.py", line 1186, in _fetch_all
    self._result_cache = list(self._iterable_class(self))
  File "/opt/py3/lib/python3.6/site-packages/django/db/models/query.py", line 54, in __iter__
    results = compiler.execute_sql(chunked_fetch=self.chunked_fetch, chunk_size=self.chunk_size)
  File "/opt/py3/lib/python3.6/site-packages/django/db/models/sql/compiler.py", line 1052, in execute_sql
    sql, params = self.as_sql()
  File "/opt/py3/lib/python3.6/site-packages/django/db/models/sql/compiler.py", line 464, in as_sql
    where, w_params = self.compile(self.where) if self.where is not None else ("", [])
  File "/opt/py3/lib/python3.6/site-packages/django/db/models/sql/compiler.py", line 390, in compile
    sql, params = node.as_sql(self, self.connection)
  File "/opt/py3/lib/python3.6/site-packages/django/db/models/sql/where.py", line 81, in as_sql
    sql, params = compiler.compile(child)
  File "/opt/py3/lib/python3.6/site-packages/django/db/models/sql/compiler.py", line 390, in compile
    sql, params = node.as_sql(self, self.connection)
  File "/opt/py3/lib/python3.6/site-packages/django/db/models/fields/related_lookups.py", line 130, in as_sql
    return super().as_sql(compiler, connection)
  File "/opt/py3/lib/python3.6/site-packages/django/db/models/lookups.py", line 163, in as_sql
    rhs_sql, rhs_params = self.process_rhs(compiler, connection)
  File "/opt/py3/lib/python3.6/site-packages/django/db/models/lookups.py", line 260, in process_rhs
    return super().process_rhs(compiler, connection)
  File "/opt/py3/lib/python3.6/site-packages/django/db/models/lookups.py", line 95, in process_rhs
    return self.get_db_prep_lookup(value, connection)
  File "/opt/py3/lib/python3.6/site-packages/django/db/models/lookups.py", line 187, in get_db_prep_lookup
    [get_db_prep_value(value, connection, prepared=True)]
  File "/opt/py3/lib/python3.6/site-packages/django/db/models/fields/related.py", line 940, in get_db_prep_value
    return self.target_field.get_db_prep_value(value, connection, prepared)
  File "/opt/py3/lib/python3.6/site-packages/django/db/models/fields/__init__.py", line 2316, in get_db_prep_value
    value = self.to_python(value)
  File "/opt/py3/lib/python3.6/site-packages/django/db/models/fields/__init__.py", line 2330, in to_python
    params={'value': value},
django.core.exceptions.ValidationError: ['‘ww’不是有效UUID。']
2019-02-21 09:34:34 [log ERROR] Internal Server Error: /api/perms/v1/user/nodes-assets/tree/
Traceback (most recent call last):
  File "/opt/py3/lib/python3.6/site-packages/django/db/models/fields/__init__.py", line 2325, in to_python
    return uuid.UUID(value)
  File "/usr/local/lib/python3.6/uuid.py", line 140, in __init__
    raise ValueError('badly formed hexadecimal UUID string')
ValueError: badly formed hexadecimal UUID string

During handling of the above exception, another exception occurred:

Traceback (most recent call last):
  File "/opt/py3/lib/python3.6/site-packages/django/core/handlers/exception.py", line 34, in inner
    response = get_response(request)
  File "/opt/py3/lib/python3.6/site-packages/django/core/handlers/base.py", line 126, in _get_response
    response = self.process_exception_by_middleware(e, request)
  File "/opt/py3/lib/python3.6/site-packages/django/core/handlers/base.py", line 124, in _get_response
    response = wrapped_callback(request, *callback_args, **callback_kwargs)
  File "/usr/local/lib/python3.6/contextlib.py", line 53, in inner
    return func(*args, **kwds)
  File "/opt/py3/lib/python3.6/site-packages/django/views/decorators/csrf.py", line 54, in wrapped_view
    return view_func(*args, **kwargs)
  File "/opt/py3/lib/python3.6/site-packages/django/views/generic/base.py", line 68, in view
    return self.dispatch(request, *args, **kwargs)
  File "/opt/py3/lib/python3.6/site-packages/rest_framework/views.py", line 483, in dispatch
    response = self.handle_exception(exc)
  File "/opt/py3/lib/python3.6/site-packages/rest_framework/views.py", line 443, in handle_exception
    self.raise_uncaught_exception(exc)
  File "/opt/py3/lib/python3.6/site-packages/rest_framework/views.py", line 480, in dispatch
    response = handler(request, *args, **kwargs)
  File "/opt/jumpserver/apps/perms/api.py", line 299, in get
    return super().get(request, *args, **kwargs)
  File "/opt/py3/lib/python3.6/site-packages/rest_framework/generics.py", line 201, in get
    return self.list(request, *args, **kwargs)
  File "/opt/py3/lib/python3.6/site-packages/rest_framework/mixins.py", line 40, in list
    queryset = self.filter_queryset(self.get_queryset())
  File "/opt/jumpserver/apps/perms/api.py", line 382, in get_queryset
    nodes = util.get_nodes_with_assets()
  File "/opt/jumpserver/apps/perms/utils.py", line 163, in get_nodes_with_assets
    assets = self.get_assets()
  File "/opt/jumpserver/apps/perms/utils.py", line 146, in get_assets
    assets = self.get_assets_direct()
  File "/opt/jumpserver/apps/perms/utils.py", line 135, in get_assets_direct
    permissions = self.permissions.prefetch_related('assets', 'system_users')
  File "/opt/jumpserver/apps/perms/utils.py", line 106, in permissions
    if self._permissions:
  File "/opt/py3/lib/python3.6/site-packages/django/db/models/query.py", line 272, in __bool__
    self._fetch_all()
  File "/opt/py3/lib/python3.6/site-packages/django/db/models/query.py", line 1186, in _fetch_all
    self._result_cache = list(self._iterable_class(self))
  File "/opt/py3/lib/python3.6/site-packages/django/db/models/query.py", line 54, in __iter__
    results = compiler.execute_sql(chunked_fetch=self.chunked_fetch, chunk_size=self.chunk_size)
  File "/opt/py3/lib/python3.6/site-packages/django/db/models/sql/compiler.py", line 1052, in execute_sql
    sql, params = self.as_sql()
  File "/opt/py3/lib/python3.6/site-packages/django/db/models/sql/compiler.py", line 464, in as_sql
    where, w_params = self.compile(self.where) if self.where is not None else ("", [])
  File "/opt/py3/lib/python3.6/site-packages/django/db/models/sql/compiler.py", line 390, in compile
    sql, params = node.as_sql(self, self.connection)
  File "/opt/py3/lib/python3.6/site-packages/django/db/models/sql/where.py", line 81, in as_sql
    sql, params = compiler.compile(child)
  File "/opt/py3/lib/python3.6/site-packages/django/db/models/sql/compiler.py", line 390, in compile
    sql, params = node.as_sql(self, self.connection)
  File "/opt/py3/lib/python3.6/site-packages/django/db/models/fields/related_lookups.py", line 130, in as_sql
    return super().as_sql(compiler, connection)
  File "/opt/py3/lib/python3.6/site-packages/django/db/models/lookups.py", line 163, in as_sql
    rhs_sql, rhs_params = self.process_rhs(compiler, connection)
  File "/opt/py3/lib/python3.6/site-packages/django/db/models/lookups.py", line 260, in process_rhs
    return super().process_rhs(compiler, connection)
  File "/opt/py3/lib/python3.6/site-packages/django/db/models/lookups.py", line 95, in process_rhs
    return self.get_db_prep_lookup(value, connection)
  File "/opt/py3/lib/python3.6/site-packages/django/db/models/lookups.py", line 187, in get_db_prep_lookup
    [get_db_prep_value(value, connection, prepared=True)]
  File "/opt/py3/lib/python3.6/site-packages/django/db/models/fields/related.py", line 940, in get_db_prep_value
    return self.target_field.get_db_prep_value(value, connection, prepared)
  File "/opt/py3/lib/python3.6/site-packages/django/db/models/fields/__init__.py", line 2316, in get_db_prep_value
    value = self.to_python(value)
  File "/opt/py3/lib/python3.6/site-packages/django/db/models/fields/__init__.py", line 2330, in to_python
    params={'value': value},
django.core.exceptions.ValidationError: ['‘ww’不是有效UUID。']
2019-02-21 09:35:19 [log ERROR] Internal Server Error: /api/perms/v1/user/nodes-assets/tree/
Traceback (most recent call last):
  File "/opt/py3/lib/python3.6/site-packages/django/db/models/fields/__init__.py", line 2325, in to_python
    return uuid.UUID(value)
  File "/usr/local/lib/python3.6/uuid.py", line 140, in __init__
    raise ValueError('badly formed hexadecimal UUID string')
ValueError: badly formed hexadecimal UUID string

During handling of the above exception, another exception occurred:

Traceback (most recent call last):
  File "/opt/py3/lib/python3.6/site-packages/django/core/handlers/exception.py", line 34, in inner
    response = get_response(request)
  File "/opt/py3/lib/python3.6/site-packages/django/core/handlers/base.py", line 126, in _get_response
    response = self.process_exception_by_middleware(e, request)
  File "/opt/py3/lib/python3.6/site-packages/django/core/handlers/base.py", line 124, in _get_response
    response = wrapped_callback(request, *callback_args, **callback_kwargs)
  File "/usr/local/lib/python3.6/contextlib.py", line 53, in inner
    return func(*args, **kwds)
  File "/opt/py3/lib/python3.6/site-packages/django/views/decorators/csrf.py", line 54, in wrapped_view
    return view_func(*args, **kwargs)
  File "/opt/py3/lib/python3.6/site-packages/django/views/generic/base.py", line 68, in view
    return self.dispatch(request, *args, **kwargs)
  File "/opt/py3/lib/python3.6/site-packages/rest_framework/views.py", line 483, in dispatch
    response = self.handle_exception(exc)
  File "/opt/py3/lib/python3.6/site-packages/rest_framework/views.py", line 443, in handle_exception
    self.raise_uncaught_exception(exc)
  File "/opt/py3/lib/python3.6/site-packages/rest_framework/views.py", line 480, in dispatch
    response = handler(request, *args, **kwargs)
  File "/opt/jumpserver/apps/perms/api.py", line 299, in get
    return super().get(request, *args, **kwargs)
  File "/opt/py3/lib/python3.6/site-packages/rest_framework/generics.py", line 201, in get
    return self.list(request, *args, **kwargs)
  File "/opt/py3/lib/python3.6/site-packages/rest_framework/mixins.py", line 40, in list
    queryset = self.filter_queryset(self.get_queryset())
  File "/opt/jumpserver/apps/perms/api.py", line 382, in get_queryset
    nodes = util.get_nodes_with_assets()
  File "/opt/jumpserver/apps/perms/utils.py", line 163, in get_nodes_with_assets
    assets = self.get_assets()
  File "/opt/jumpserver/apps/perms/utils.py", line 146, in get_assets
    assets = self.get_assets_direct()
  File "/opt/jumpserver/apps/perms/utils.py", line 135, in get_assets_direct
    permissions = self.permissions.prefetch_related('assets', 'system_users')
  File "/opt/jumpserver/apps/perms/utils.py", line 106, in permissions
    if self._permissions:
  File "/opt/py3/lib/python3.6/site-packages/django/db/models/query.py", line 272, in __bool__
    self._fetch_all()
  File "/opt/py3/lib/python3.6/site-packages/django/db/models/query.py", line 1186, in _fetch_all
    self._result_cache = list(self._iterable_class(self))
  File "/opt/py3/lib/python3.6/site-packages/django/db/models/query.py", line 54, in __iter__
    results = compiler.execute_sql(chunked_fetch=self.chunked_fetch, chunk_size=self.chunk_size)
  File "/opt/py3/lib/python3.6/site-packages/django/db/models/sql/compiler.py", line 1052, in execute_sql
    sql, params = self.as_sql()
  File "/opt/py3/lib/python3.6/site-packages/django/db/models/sql/compiler.py", line 464, in as_sql
    where, w_params = self.compile(self.where) if self.where is not None else ("", [])
  File "/opt/py3/lib/python3.6/site-packages/django/db/models/sql/compiler.py", line 390, in compile
    sql, params = node.as_sql(self, self.connection)
  File "/opt/py3/lib/python3.6/site-packages/django/db/models/sql/where.py", line 81, in as_sql
    sql, params = compiler.compile(child)
  File "/opt/py3/lib/python3.6/site-packages/django/db/models/sql/compiler.py", line 390, in compile
    sql, params = node.as_sql(self, self.connection)
  File "/opt/py3/lib/python3.6/site-packages/django/db/models/fields/related_lookups.py", line 130, in as_sql
    return super().as_sql(compiler, connection)
  File "/opt/py3/lib/python3.6/site-packages/django/db/models/lookups.py", line 163, in as_sql
    rhs_sql, rhs_params = self.process_rhs(compiler, connection)
  File "/opt/py3/lib/python3.6/site-packages/django/db/models/lookups.py", line 260, in process_rhs
    return super().process_rhs(compiler, connection)
  File "/opt/py3/lib/python3.6/site-packages/django/db/models/lookups.py", line 95, in process_rhs
    return self.get_db_prep_lookup(value, connection)
  File "/opt/py3/lib/python3.6/site-packages/django/db/models/lookups.py", line 187, in get_db_prep_lookup
    [get_db_prep_value(value, connection, prepared=True)]
  File "/opt/py3/lib/python3.6/site-packages/django/db/models/fields/related.py", line 940, in get_db_prep_value
    return self.target_field.get_db_prep_value(value, connection, prepared)
  File "/opt/py3/lib/python3.6/site-packages/django/db/models/fields/__init__.py", line 2316, in get_db_prep_value
    value = self.to_python(value)
  File "/opt/py3/lib/python3.6/site-packages/django/db/models/fields/__init__.py", line 2330, in to_python
    params={'value': value},
django.core.exceptions.ValidationError: ['‘qq’不是有效UUID。']
2019-02-21 09:36:12 [log ERROR] Internal Server Error: /api/perms/v1/user/nodes-assets/tree/
Traceback (most recent call last):
  File "/opt/py3/lib/python3.6/site-packages/django/db/models/fields/__init__.py", line 2325, in to_python
    return uuid.UUID(value)
  File "/usr/local/lib/python3.6/uuid.py", line 140, in __init__
    raise ValueError('badly formed hexadecimal UUID string')
ValueError: badly formed hexadecimal UUID string

During handling of the above exception, another exception occurred:

Traceback (most recent call last):
  File "/opt/py3/lib/python3.6/site-packages/django/core/handlers/exception.py", line 34, in inner
    response = get_response(request)
  File "/opt/py3/lib/python3.6/site-packages/django/core/handlers/base.py", line 126, in _get_response
    response = self.process_exception_by_middleware(e, request)
  File "/opt/py3/lib/python3.6/site-packages/django/core/handlers/base.py", line 124, in _get_response
    response = wrapped_callback(request, *callback_args, **callback_kwargs)
  File "/usr/local/lib/python3.6/contextlib.py", line 53, in inner
    return func(*args, **kwds)
  File "/opt/py3/lib/python3.6/site-packages/django/views/decorators/csrf.py", line 54, in wrapped_view
    return view_func(*args, **kwargs)
  File "/opt/py3/lib/python3.6/site-packages/django/views/generic/base.py", line 68, in view
    return self.dispatch(request, *args, **kwargs)
  File "/opt/py3/lib/python3.6/site-packages/rest_framework/views.py", line 483, in dispatch
    response = self.handle_exception(exc)
  File "/opt/py3/lib/python3.6/site-packages/rest_framework/views.py", line 443, in handle_exception
    self.raise_uncaught_exception(exc)
  File "/opt/py3/lib/python3.6/site-packages/rest_framework/views.py", line 480, in dispatch
    response = handler(request, *args, **kwargs)
  File "/opt/jumpserver/apps/perms/api.py", line 299, in get
    return super().get(request, *args, **kwargs)
  File "/opt/py3/lib/python3.6/site-packages/rest_framework/generics.py", line 201, in get
    return self.list(request, *args, **kwargs)
  File "/opt/py3/lib/python3.6/site-packages/rest_framework/mixins.py", line 40, in list
    queryset = self.filter_queryset(self.get_queryset())
  File "/opt/jumpserver/apps/perms/api.py", line 382, in get_queryset
    nodes = util.get_nodes_with_assets()
  File "/opt/jumpserver/apps/perms/utils.py", line 163, in get_nodes_with_assets
    assets = self.get_assets()
  File "/opt/jumpserver/apps/perms/utils.py", line 146, in get_assets
    assets = self.get_assets_direct()
  File "/opt/jumpserver/apps/perms/utils.py", line 135, in get_assets_direct
    permissions = self.permissions.prefetch_related('assets', 'system_users')
  File "/opt/jumpserver/apps/perms/utils.py", line 106, in permissions
    if self._permissions:
  File "/opt/py3/lib/python3.6/site-packages/django/db/models/query.py", line 272, in __bool__
    self._fetch_all()
  File "/opt/py3/lib/python3.6/site-packages/django/db/models/query.py", line 1186, in _fetch_all
    self._result_cache = list(self._iterable_class(self))
  File "/opt/py3/lib/python3.6/site-packages/django/db/models/query.py", line 54, in __iter__
    results = compiler.execute_sql(chunked_fetch=self.chunked_fetch, chunk_size=self.chunk_size)
  File "/opt/py3/lib/python3.6/site-packages/django/db/models/sql/compiler.py", line 1052, in execute_sql
    sql, params = self.as_sql()
  File "/opt/py3/lib/python3.6/site-packages/django/db/models/sql/compiler.py", line 464, in as_sql
    where, w_params = self.compile(self.where) if self.where is not None else ("", [])
  File "/opt/py3/lib/python3.6/site-packages/django/db/models/sql/compiler.py", line 390, in compile
    sql, params = node.as_sql(self, self.connection)
  File "/opt/py3/lib/python3.6/site-packages/django/db/models/sql/where.py", line 81, in as_sql
    sql, params = compiler.compile(child)
  File "/opt/py3/lib/python3.6/site-packages/django/db/models/sql/compiler.py", line 390, in compile
    sql, params = node.as_sql(self, self.connection)
  File "/opt/py3/lib/python3.6/site-packages/django/db/models/fields/related_lookups.py", line 130, in as_sql
    return super().as_sql(compiler, connection)
  File "/opt/py3/lib/python3.6/site-packages/django/db/models/lookups.py", line 163, in as_sql
    rhs_sql, rhs_params = self.process_rhs(compiler, connection)
  File "/opt/py3/lib/python3.6/site-packages/django/db/models/lookups.py", line 260, in process_rhs
    return super().process_rhs(compiler, connection)
  File "/opt/py3/lib/python3.6/site-packages/django/db/models/lookups.py", line 95, in process_rhs
    return self.get_db_prep_lookup(value, connection)
  File "/opt/py3/lib/python3.6/site-packages/django/db/models/lookups.py", line 187, in get_db_prep_lookup
    [get_db_prep_value(value, connection, prepared=True)]
  File "/opt/py3/lib/python3.6/site-packages/django/db/models/fields/related.py", line 940, in get_db_prep_value
    return self.target_field.get_db_prep_value(value, connection, prepared)
  File "/opt/py3/lib/python3.6/site-packages/django/db/models/fields/__init__.py", line 2316, in get_db_prep_value
    value = self.to_python(value)
  File "/opt/py3/lib/python3.6/site-packages/django/db/models/fields/__init__.py", line 2330, in to_python
    params={'value': value},
django.core.exceptions.ValidationError: ['‘qq’不是有效UUID。']
2019-02-21 09:36:30 [log ERROR] Internal Server Error: /api/perms/v1/user/nodes-assets/tree/
Traceback (most recent call last):
  File "/opt/py3/lib/python3.6/site-packages/django/db/models/fields/__init__.py", line 2325, in to_python
    return uuid.UUID(value)
  File "/usr/local/lib/python3.6/uuid.py", line 140, in __init__
    raise ValueError('badly formed hexadecimal UUID string')
ValueError: badly formed hexadecimal UUID string

During handling of the above exception, another exception occurred:

Traceback (most recent call last):
  File "/opt/py3/lib/python3.6/site-packages/django/core/handlers/exception.py", line 34, in inner
    response = get_response(request)
  File "/opt/py3/lib/python3.6/site-packages/django/core/handlers/base.py", line 126, in _get_response
    response = self.process_exception_by_middleware(e, request)
  File "/opt/py3/lib/python3.6/site-packages/django/core/handlers/base.py", line 124, in _get_response
    response = wrapped_callback(request, *callback_args, **callback_kwargs)
  File "/usr/local/lib/python3.6/contextlib.py", line 53, in inner
    return func(*args, **kwds)
  File "/opt/py3/lib/python3.6/site-packages/django/views/decorators/csrf.py", line 54, in wrapped_view
    return view_func(*args, **kwargs)
  File "/opt/py3/lib/python3.6/site-packages/django/views/generic/base.py", line 68, in view
    return self.dispatch(request, *args, **kwargs)
  File "/opt/py3/lib/python3.6/site-packages/rest_framework/views.py", line 483, in dispatch
    response = self.handle_exception(exc)
  File "/opt/py3/lib/python3.6/site-packages/rest_framework/views.py", line 443, in handle_exception
    self.raise_uncaught_exception(exc)
  File "/opt/py3/lib/python3.6/site-packages/rest_framework/views.py", line 480, in dispatch
    response = handler(request, *args, **kwargs)
  File "/opt/jumpserver/apps/perms/api.py", line 299, in get
    return super().get(request, *args, **kwargs)
  File "/opt/py3/lib/python3.6/site-packages/rest_framework/generics.py", line 201, in get
    return self.list(request, *args, **kwargs)
  File "/opt/py3/lib/python3.6/site-packages/rest_framework/mixins.py", line 40, in list
    queryset = self.filter_queryset(self.get_queryset())
  File "/opt/jumpserver/apps/perms/api.py", line 382, in get_queryset
    nodes = util.get_nodes_with_assets()
  File "/opt/jumpserver/apps/perms/utils.py", line 163, in get_nodes_with_assets
    assets = self.get_assets()
  File "/opt/jumpserver/apps/perms/utils.py", line 146, in get_assets
    assets = self.get_assets_direct()
  File "/opt/jumpserver/apps/perms/utils.py", line 135, in get_assets_direct
    permissions = self.permissions.prefetch_related('assets', 'system_users')
  File "/opt/jumpserver/apps/perms/utils.py", line 106, in permissions
    if self._permissions:
  File "/opt/py3/lib/python3.6/site-packages/django/db/models/query.py", line 272, in __bool__
    self._fetch_all()
  File "/opt/py3/lib/python3.6/site-packages/django/db/models/query.py", line 1186, in _fetch_all
    self._result_cache = list(self._iterable_class(self))
  File "/opt/py3/lib/python3.6/site-packages/django/db/models/query.py", line 54, in __iter__
    results = compiler.execute_sql(chunked_fetch=self.chunked_fetch, chunk_size=self.chunk_size)
  File "/opt/py3/lib/python3.6/site-packages/django/db/models/sql/compiler.py", line 1052, in execute_sql
    sql, params = self.as_sql()
  File "/opt/py3/lib/python3.6/site-packages/django/db/models/sql/compiler.py", line 464, in as_sql
    where, w_params = self.compile(self.where) if self.where is not None else ("", [])
  File "/opt/py3/lib/python3.6/site-packages/django/db/models/sql/compiler.py", line 390, in compile
    sql, params = node.as_sql(self, self.connection)
  File "/opt/py3/lib/python3.6/site-packages/django/db/models/sql/where.py", line 81, in as_sql
    sql, params = compiler.compile(child)
  File "/opt/py3/lib/python3.6/site-packages/django/db/models/sql/compiler.py", line 390, in compile
    sql, params = node.as_sql(self, self.connection)
  File "/opt/py3/lib/python3.6/site-packages/django/db/models/fields/related_lookups.py", line 130, in as_sql
    return super().as_sql(compiler, connection)
  File "/opt/py3/lib/python3.6/site-packages/django/db/models/lookups.py", line 163, in as_sql
    rhs_sql, rhs_params = self.process_rhs(compiler, connection)
  File "/opt/py3/lib/python3.6/site-packages/django/db/models/lookups.py", line 260, in process_rhs
    return super().process_rhs(compiler, connection)
  File "/opt/py3/lib/python3.6/site-packages/django/db/models/lookups.py", line 95, in process_rhs
    return self.get_db_prep_lookup(value, connection)
  File "/opt/py3/lib/python3.6/site-packages/django/db/models/lookups.py", line 187, in get_db_prep_lookup
    [get_db_prep_value(value, connection, prepared=True)]
  File "/opt/py3/lib/python3.6/site-packages/django/db/models/fields/related.py", line 940, in get_db_prep_value
    return self.target_field.get_db_prep_value(value, connection, prepared)
  File "/opt/py3/lib/python3.6/site-packages/django/db/models/fields/__init__.py", line 2316, in get_db_prep_value
    value = self.to_python(value)
  File "/opt/py3/lib/python3.6/site-packages/django/db/models/fields/__init__.py", line 2330, in to_python
    params={'value': value},
django.core.exceptions.ValidationError: ['‘qq’不是有效UUID。']
2019-02-21 17:54:01 [tasks ERROR] Sending mail error: [Errno -2] Name or service not known
2019-02-22 14:05:40 [log ERROR] Internal Server Error: /api/dbaudits/v1/mongosubmit/
Traceback (most recent call last):
  File "/opt/py3/lib/python3.6/site-packages/django/db/backends/utils.py", line 85, in _execute
    return self.cursor.execute(sql, params)
  File "/opt/py3/lib/python3.6/site-packages/django/db/backends/mysql/base.py", line 71, in execute
    return self.cursor.execute(query, args)
  File "/opt/py3/lib/python3.6/site-packages/MySQLdb/cursors.py", line 255, in execute
    self.errorhandler(self, exc, value)
  File "/opt/py3/lib/python3.6/site-packages/MySQLdb/connections.py", line 50, in defaulterrorhandler
    raise errorvalue
  File "/opt/py3/lib/python3.6/site-packages/MySQLdb/cursors.py", line 252, in execute
    res = self._query(query)
  File "/opt/py3/lib/python3.6/site-packages/MySQLdb/cursors.py", line 378, in _query
    db.query(q)
  File "/opt/py3/lib/python3.6/site-packages/MySQLdb/connections.py", line 280, in query
    _mysql.connection.query(self, query)
_mysql_exceptions.ProgrammingError: (1146, "Table 'jumpserver.dbaudits_mongosubmit' doesn't exist")

The above exception was the direct cause of the following exception:

Traceback (most recent call last):
  File "/opt/py3/lib/python3.6/site-packages/django/core/handlers/exception.py", line 34, in inner
    response = get_response(request)
  File "/opt/py3/lib/python3.6/site-packages/django/core/handlers/base.py", line 126, in _get_response
    response = self.process_exception_by_middleware(e, request)
  File "/opt/py3/lib/python3.6/site-packages/django/core/handlers/base.py", line 124, in _get_response
    response = wrapped_callback(request, *callback_args, **callback_kwargs)
  File "/usr/local/lib/python3.6/contextlib.py", line 53, in inner
    return func(*args, **kwds)
  File "/opt/py3/lib/python3.6/site-packages/django/views/decorators/csrf.py", line 54, in wrapped_view
    return view_func(*args, **kwargs)
  File "/opt/py3/lib/python3.6/site-packages/rest_framework/viewsets.py", line 103, in view
    return self.dispatch(request, *args, **kwargs)
  File "/opt/py3/lib/python3.6/site-packages/rest_framework/views.py", line 483, in dispatch
    response = self.handle_exception(exc)
  File "/opt/py3/lib/python3.6/site-packages/rest_framework/views.py", line 443, in handle_exception
    self.raise_uncaught_exception(exc)
  File "/opt/py3/lib/python3.6/site-packages/rest_framework/views.py", line 480, in dispatch
    response = handler(request, *args, **kwargs)
  File "/opt/py3/lib/python3.6/site-packages/rest_framework/mixins.py", line 48, in list
    return Response(serializer.data)
  File "/opt/py3/lib/python3.6/site-packages/rest_framework/serializers.py", line 765, in data
    ret = super(ListSerializer, self).data
  File "/opt/py3/lib/python3.6/site-packages/rest_framework/serializers.py", line 262, in data
    self._data = self.to_representation(self.instance)
  File "/opt/py3/lib/python3.6/site-packages/rest_framework/serializers.py", line 683, in to_representation
    self.child.to_representation(item) for item in iterable
  File "/opt/py3/lib/python3.6/site-packages/django/db/models/query.py", line 268, in __iter__
    self._fetch_all()
  File "/opt/py3/lib/python3.6/site-packages/django/db/models/query.py", line 1186, in _fetch_all
    self._result_cache = list(self._iterable_class(self))
  File "/opt/py3/lib/python3.6/site-packages/django/db/models/query.py", line 54, in __iter__
    results = compiler.execute_sql(chunked_fetch=self.chunked_fetch, chunk_size=self.chunk_size)
  File "/opt/py3/lib/python3.6/site-packages/django/db/models/sql/compiler.py", line 1065, in execute_sql
    cursor.execute(sql, params)
  File "/opt/py3/lib/python3.6/site-packages/django/db/backends/utils.py", line 68, in execute
    return self._execute_with_wrappers(sql, params, many=False, executor=self._execute)
  File "/opt/py3/lib/python3.6/site-packages/django/db/backends/utils.py", line 77, in _execute_with_wrappers
    return executor(sql, params, many, context)
  File "/opt/py3/lib/python3.6/site-packages/django/db/backends/utils.py", line 85, in _execute
    return self.cursor.execute(sql, params)
  File "/opt/py3/lib/python3.6/site-packages/django/db/utils.py", line 89, in __exit__
    raise dj_exc_value.with_traceback(traceback) from exc_value
  File "/opt/py3/lib/python3.6/site-packages/django/db/backends/utils.py", line 85, in _execute
    return self.cursor.execute(sql, params)
  File "/opt/py3/lib/python3.6/site-packages/django/db/backends/mysql/base.py", line 71, in execute
    return self.cursor.execute(query, args)
  File "/opt/py3/lib/python3.6/site-packages/MySQLdb/cursors.py", line 255, in execute
    self.errorhandler(self, exc, value)
  File "/opt/py3/lib/python3.6/site-packages/MySQLdb/connections.py", line 50, in defaulterrorhandler
    raise errorvalue
  File "/opt/py3/lib/python3.6/site-packages/MySQLdb/cursors.py", line 252, in execute
    res = self._query(query)
  File "/opt/py3/lib/python3.6/site-packages/MySQLdb/cursors.py", line 378, in _query
    db.query(q)
  File "/opt/py3/lib/python3.6/site-packages/MySQLdb/connections.py", line 280, in query
    _mysql.connection.query(self, query)
django.db.utils.ProgrammingError: (1146, "Table 'jumpserver.dbaudits_mongosubmit' doesn't exist")
2019-02-22 14:23:44 [log ERROR] Internal Server Error: /api/dbaudits/v1/mongosubmit/
Traceback (most recent call last):
  File "/opt/py3/lib/python3.6/site-packages/django/db/backends/utils.py", line 85, in _execute
    return self.cursor.execute(sql, params)
  File "/opt/py3/lib/python3.6/site-packages/django/db/backends/mysql/base.py", line 71, in execute
    return self.cursor.execute(query, args)
  File "/opt/py3/lib/python3.6/site-packages/MySQLdb/cursors.py", line 255, in execute
    self.errorhandler(self, exc, value)
  File "/opt/py3/lib/python3.6/site-packages/MySQLdb/connections.py", line 50, in defaulterrorhandler
    raise errorvalue
  File "/opt/py3/lib/python3.6/site-packages/MySQLdb/cursors.py", line 252, in execute
    res = self._query(query)
  File "/opt/py3/lib/python3.6/site-packages/MySQLdb/cursors.py", line 378, in _query
    db.query(q)
  File "/opt/py3/lib/python3.6/site-packages/MySQLdb/connections.py", line 280, in query
    _mysql.connection.query(self, query)
_mysql_exceptions.ProgrammingError: (1146, "Table 'jumpserver.dbaudits_mongosubmit' doesn't exist")

The above exception was the direct cause of the following exception:

Traceback (most recent call last):
  File "/opt/py3/lib/python3.6/site-packages/django/core/handlers/exception.py", line 34, in inner
    response = get_response(request)
  File "/opt/py3/lib/python3.6/site-packages/django/core/handlers/base.py", line 126, in _get_response
    response = self.process_exception_by_middleware(e, request)
  File "/opt/py3/lib/python3.6/site-packages/django/core/handlers/base.py", line 124, in _get_response
    response = wrapped_callback(request, *callback_args, **callback_kwargs)
  File "/usr/local/lib/python3.6/contextlib.py", line 53, in inner
    return func(*args, **kwds)
  File "/opt/py3/lib/python3.6/site-packages/django/views/decorators/csrf.py", line 54, in wrapped_view
    return view_func(*args, **kwargs)
  File "/opt/py3/lib/python3.6/site-packages/rest_framework/viewsets.py", line 103, in view
    return self.dispatch(request, *args, **kwargs)
  File "/opt/py3/lib/python3.6/site-packages/rest_framework/views.py", line 483, in dispatch
    response = self.handle_exception(exc)
  File "/opt/py3/lib/python3.6/site-packages/rest_framework/views.py", line 443, in handle_exception
    self.raise_uncaught_exception(exc)
  File "/opt/py3/lib/python3.6/site-packages/rest_framework/views.py", line 480, in dispatch
    response = handler(request, *args, **kwargs)
  File "/opt/py3/lib/python3.6/site-packages/rest_framework/mixins.py", line 48, in list
    return Response(serializer.data)
  File "/opt/py3/lib/python3.6/site-packages/rest_framework/serializers.py", line 765, in data
    ret = super(ListSerializer, self).data
  File "/opt/py3/lib/python3.6/site-packages/rest_framework/serializers.py", line 262, in data
    self._data = self.to_representation(self.instance)
  File "/opt/py3/lib/python3.6/site-packages/rest_framework/serializers.py", line 683, in to_representation
    self.child.to_representation(item) for item in iterable
  File "/opt/py3/lib/python3.6/site-packages/django/db/models/query.py", line 268, in __iter__
    self._fetch_all()
  File "/opt/py3/lib/python3.6/site-packages/django/db/models/query.py", line 1186, in _fetch_all
    self._result_cache = list(self._iterable_class(self))
  File "/opt/py3/lib/python3.6/site-packages/django/db/models/query.py", line 54, in __iter__
    results = compiler.execute_sql(chunked_fetch=self.chunked_fetch, chunk_size=self.chunk_size)
  File "/opt/py3/lib/python3.6/site-packages/django/db/models/sql/compiler.py", line 1065, in execute_sql
    cursor.execute(sql, params)
  File "/opt/py3/lib/python3.6/site-packages/django/db/backends/utils.py", line 68, in execute
    return self._execute_with_wrappers(sql, params, many=False, executor=self._execute)
  File "/opt/py3/lib/python3.6/site-packages/django/db/backends/utils.py", line 77, in _execute_with_wrappers
    return executor(sql, params, many, context)
  File "/opt/py3/lib/python3.6/site-packages/django/db/backends/utils.py", line 85, in _execute
    return self.cursor.execute(sql, params)
  File "/opt/py3/lib/python3.6/site-packages/django/db/utils.py", line 89, in __exit__
    raise dj_exc_value.with_traceback(traceback) from exc_value
  File "/opt/py3/lib/python3.6/site-packages/django/db/backends/utils.py", line 85, in _execute
    return self.cursor.execute(sql, params)
  File "/opt/py3/lib/python3.6/site-packages/django/db/backends/mysql/base.py", line 71, in execute
    return self.cursor.execute(query, args)
  File "/opt/py3/lib/python3.6/site-packages/MySQLdb/cursors.py", line 255, in execute
    self.errorhandler(self, exc, value)
  File "/opt/py3/lib/python3.6/site-packages/MySQLdb/connections.py", line 50, in defaulterrorhandler
    raise errorvalue
  File "/opt/py3/lib/python3.6/site-packages/MySQLdb/cursors.py", line 252, in execute
    res = self._query(query)
  File "/opt/py3/lib/python3.6/site-packages/MySQLdb/cursors.py", line 378, in _query
    db.query(q)
  File "/opt/py3/lib/python3.6/site-packages/MySQLdb/connections.py", line 280, in query
    _mysql.connection.query(self, query)
django.db.utils.ProgrammingError: (1146, "Table 'jumpserver.dbaudits_mongosubmit' doesn't exist")
2019-02-22 14:24:55 [log ERROR] Internal Server Error: /api/dbaudits/v1/mongosubmit/
Traceback (most recent call last):
  File "/opt/py3/lib/python3.6/site-packages/django/db/backends/utils.py", line 85, in _execute
    return self.cursor.execute(sql, params)
  File "/opt/py3/lib/python3.6/site-packages/django/db/backends/mysql/base.py", line 71, in execute
    return self.cursor.execute(query, args)
  File "/opt/py3/lib/python3.6/site-packages/MySQLdb/cursors.py", line 255, in execute
    self.errorhandler(self, exc, value)
  File "/opt/py3/lib/python3.6/site-packages/MySQLdb/connections.py", line 50, in defaulterrorhandler
    raise errorvalue
  File "/opt/py3/lib/python3.6/site-packages/MySQLdb/cursors.py", line 252, in execute
    res = self._query(query)
  File "/opt/py3/lib/python3.6/site-packages/MySQLdb/cursors.py", line 378, in _query
    db.query(q)
  File "/opt/py3/lib/python3.6/site-packages/MySQLdb/connections.py", line 280, in query
    _mysql.connection.query(self, query)
_mysql_exceptions.ProgrammingError: (1146, "Table 'jumpserver.dbaudits_mongosubmit' doesn't exist")

The above exception was the direct cause of the following exception:

Traceback (most recent call last):
  File "/opt/py3/lib/python3.6/site-packages/django/core/handlers/exception.py", line 34, in inner
    response = get_response(request)
  File "/opt/py3/lib/python3.6/site-packages/django/core/handlers/base.py", line 126, in _get_response
    response = self.process_exception_by_middleware(e, request)
  File "/opt/py3/lib/python3.6/site-packages/django/core/handlers/base.py", line 124, in _get_response
    response = wrapped_callback(request, *callback_args, **callback_kwargs)
  File "/usr/local/lib/python3.6/contextlib.py", line 53, in inner
    return func(*args, **kwds)
  File "/opt/py3/lib/python3.6/site-packages/django/views/decorators/csrf.py", line 54, in wrapped_view
    return view_func(*args, **kwargs)
  File "/opt/py3/lib/python3.6/site-packages/rest_framework/viewsets.py", line 103, in view
    return self.dispatch(request, *args, **kwargs)
  File "/opt/py3/lib/python3.6/site-packages/rest_framework/views.py", line 483, in dispatch
    response = self.handle_exception(exc)
  File "/opt/py3/lib/python3.6/site-packages/rest_framework/views.py", line 443, in handle_exception
    self.raise_uncaught_exception(exc)
  File "/opt/py3/lib/python3.6/site-packages/rest_framework/views.py", line 480, in dispatch
    response = handler(request, *args, **kwargs)
  File "/opt/py3/lib/python3.6/site-packages/rest_framework/mixins.py", line 48, in list
    return Response(serializer.data)
  File "/opt/py3/lib/python3.6/site-packages/rest_framework/serializers.py", line 765, in data
    ret = super(ListSerializer, self).data
  File "/opt/py3/lib/python3.6/site-packages/rest_framework/serializers.py", line 262, in data
    self._data = self.to_representation(self.instance)
  File "/opt/py3/lib/python3.6/site-packages/rest_framework/serializers.py", line 683, in to_representation
    self.child.to_representation(item) for item in iterable
  File "/opt/py3/lib/python3.6/site-packages/django/db/models/query.py", line 268, in __iter__
    self._fetch_all()
  File "/opt/py3/lib/python3.6/site-packages/django/db/models/query.py", line 1186, in _fetch_all
    self._result_cache = list(self._iterable_class(self))
  File "/opt/py3/lib/python3.6/site-packages/django/db/models/query.py", line 54, in __iter__
    results = compiler.execute_sql(chunked_fetch=self.chunked_fetch, chunk_size=self.chunk_size)
  File "/opt/py3/lib/python3.6/site-packages/django/db/models/sql/compiler.py", line 1065, in execute_sql
    cursor.execute(sql, params)
  File "/opt/py3/lib/python3.6/site-packages/django/db/backends/utils.py", line 68, in execute
    return self._execute_with_wrappers(sql, params, many=False, executor=self._execute)
  File "/opt/py3/lib/python3.6/site-packages/django/db/backends/utils.py", line 77, in _execute_with_wrappers
    return executor(sql, params, many, context)
  File "/opt/py3/lib/python3.6/site-packages/django/db/backends/utils.py", line 85, in _execute
    return self.cursor.execute(sql, params)
  File "/opt/py3/lib/python3.6/site-packages/django/db/utils.py", line 89, in __exit__
    raise dj_exc_value.with_traceback(traceback) from exc_value
  File "/opt/py3/lib/python3.6/site-packages/django/db/backends/utils.py", line 85, in _execute
    return self.cursor.execute(sql, params)
  File "/opt/py3/lib/python3.6/site-packages/django/db/backends/mysql/base.py", line 71, in execute
    return self.cursor.execute(query, args)
  File "/opt/py3/lib/python3.6/site-packages/MySQLdb/cursors.py", line 255, in execute
    self.errorhandler(self, exc, value)
  File "/opt/py3/lib/python3.6/site-packages/MySQLdb/connections.py", line 50, in defaulterrorhandler
    raise errorvalue
  File "/opt/py3/lib/python3.6/site-packages/MySQLdb/cursors.py", line 252, in execute
    res = self._query(query)
  File "/opt/py3/lib/python3.6/site-packages/MySQLdb/cursors.py", line 378, in _query
    db.query(q)
  File "/opt/py3/lib/python3.6/site-packages/MySQLdb/connections.py", line 280, in query
    _mysql.connection.query(self, query)
django.db.utils.ProgrammingError: (1146, "Table 'jumpserver.dbaudits_mongosubmit' doesn't exist")
2019-02-22 16:15:14 [log ERROR] Internal Server Error: /api/dbaudits/v1/mongosubmit/
Traceback (most recent call last):
  File "/opt/py3/lib/python3.6/site-packages/django/core/handlers/exception.py", line 34, in inner
    response = get_response(request)
  File "/opt/py3/lib/python3.6/site-packages/django/core/handlers/base.py", line 126, in _get_response
    response = self.process_exception_by_middleware(e, request)
  File "/opt/py3/lib/python3.6/site-packages/django/core/handlers/base.py", line 124, in _get_response
    response = wrapped_callback(request, *callback_args, **callback_kwargs)
  File "/usr/local/lib/python3.6/contextlib.py", line 53, in inner
    return func(*args, **kwds)
  File "/opt/py3/lib/python3.6/site-packages/django/views/decorators/csrf.py", line 54, in wrapped_view
    return view_func(*args, **kwargs)
  File "/opt/py3/lib/python3.6/site-packages/rest_framework/viewsets.py", line 103, in view
    return self.dispatch(request, *args, **kwargs)
  File "/opt/py3/lib/python3.6/site-packages/rest_framework/views.py", line 483, in dispatch
    response = self.handle_exception(exc)
  File "/opt/py3/lib/python3.6/site-packages/rest_framework/views.py", line 443, in handle_exception
    self.raise_uncaught_exception(exc)
  File "/opt/py3/lib/python3.6/site-packages/rest_framework/views.py", line 480, in dispatch
    response = handler(request, *args, **kwargs)
  File "/opt/py3/lib/python3.6/site-packages/rest_framework/mixins.py", line 48, in list
    return Response(serializer.data)
  File "/opt/py3/lib/python3.6/site-packages/rest_framework/serializers.py", line 765, in data
    ret = super(ListSerializer, self).data
  File "/opt/py3/lib/python3.6/site-packages/rest_framework/serializers.py", line 262, in data
    self._data = self.to_representation(self.instance)
  File "/opt/py3/lib/python3.6/site-packages/rest_framework/serializers.py", line 683, in to_representation
    self.child.to_representation(item) for item in iterable
  File "/opt/py3/lib/python3.6/site-packages/django/db/models/query.py", line 268, in __iter__
    self._fetch_all()
  File "/opt/py3/lib/python3.6/site-packages/django/db/models/query.py", line 1186, in _fetch_all
    self._result_cache = list(self._iterable_class(self))
  File "/opt/py3/lib/python3.6/site-packages/django/db/models/query.py", line 63, in __iter__
    for row in compiler.results_iter(results):
  File "/opt/py3/lib/python3.6/site-packages/django/db/models/sql/compiler.py", line 1009, in apply_converters
    value = converter(value, expression, connection)
  File "/opt/py3/lib/python3.6/site-packages/django/db/backends/mysql/operations.py", line 257, in convert_uuidfield_value
    value = uuid.UUID(value)
  File "/usr/local/lib/python3.6/uuid.py", line 140, in __init__
    raise ValueError('badly formed hexadecimal UUID string')
ValueError: badly formed hexadecimal UUID string
2019-02-22 16:15:17 [log ERROR] Internal Server Error: /api/dbaudits/v1/mongosubmit/
Traceback (most recent call last):
  File "/opt/py3/lib/python3.6/site-packages/django/core/handlers/exception.py", line 34, in inner
    response = get_response(request)
  File "/opt/py3/lib/python3.6/site-packages/django/core/handlers/base.py", line 126, in _get_response
    response = self.process_exception_by_middleware(e, request)
  File "/opt/py3/lib/python3.6/site-packages/django/core/handlers/base.py", line 124, in _get_response
    response = wrapped_callback(request, *callback_args, **callback_kwargs)
  File "/usr/local/lib/python3.6/contextlib.py", line 53, in inner
    return func(*args, **kwds)
  File "/opt/py3/lib/python3.6/site-packages/django/views/decorators/csrf.py", line 54, in wrapped_view
    return view_func(*args, **kwargs)
  File "/opt/py3/lib/python3.6/site-packages/rest_framework/viewsets.py", line 103, in view
    return self.dispatch(request, *args, **kwargs)
  File "/opt/py3/lib/python3.6/site-packages/rest_framework/views.py", line 483, in dispatch
    response = self.handle_exception(exc)
  File "/opt/py3/lib/python3.6/site-packages/rest_framework/views.py", line 443, in handle_exception
    self.raise_uncaught_exception(exc)
  File "/opt/py3/lib/python3.6/site-packages/rest_framework/views.py", line 480, in dispatch
    response = handler(request, *args, **kwargs)
  File "/opt/py3/lib/python3.6/site-packages/rest_framework/mixins.py", line 48, in list
    return Response(serializer.data)
  File "/opt/py3/lib/python3.6/site-packages/rest_framework/serializers.py", line 765, in data
    ret = super(ListSerializer, self).data
  File "/opt/py3/lib/python3.6/site-packages/rest_framework/serializers.py", line 262, in data
    self._data = self.to_representation(self.instance)
  File "/opt/py3/lib/python3.6/site-packages/rest_framework/serializers.py", line 683, in to_representation
    self.child.to_representation(item) for item in iterable
  File "/opt/py3/lib/python3.6/site-packages/django/db/models/query.py", line 268, in __iter__
    self._fetch_all()
  File "/opt/py3/lib/python3.6/site-packages/django/db/models/query.py", line 1186, in _fetch_all
    self._result_cache = list(self._iterable_class(self))
  File "/opt/py3/lib/python3.6/site-packages/django/db/models/query.py", line 63, in __iter__
    for row in compiler.results_iter(results):
  File "/opt/py3/lib/python3.6/site-packages/django/db/models/sql/compiler.py", line 1009, in apply_converters
    value = converter(value, expression, connection)
  File "/opt/py3/lib/python3.6/site-packages/django/db/backends/mysql/operations.py", line 257, in convert_uuidfield_value
    value = uuid.UUID(value)
  File "/usr/local/lib/python3.6/uuid.py", line 140, in __init__
    raise ValueError('badly formed hexadecimal UUID string')
ValueError: badly formed hexadecimal UUID string
2019-02-22 16:18:31 [log ERROR] Internal Server Error: /api/dbaudits/v1/mongosubmit/
Traceback (most recent call last):
  File "/opt/py3/lib/python3.6/site-packages/django/core/handlers/exception.py", line 34, in inner
    response = get_response(request)
  File "/opt/py3/lib/python3.6/site-packages/django/core/handlers/base.py", line 126, in _get_response
    response = self.process_exception_by_middleware(e, request)
  File "/opt/py3/lib/python3.6/site-packages/django/core/handlers/base.py", line 124, in _get_response
    response = wrapped_callback(request, *callback_args, **callback_kwargs)
  File "/usr/local/lib/python3.6/contextlib.py", line 53, in inner
    return func(*args, **kwds)
  File "/opt/py3/lib/python3.6/site-packages/django/views/decorators/csrf.py", line 54, in wrapped_view
    return view_func(*args, **kwargs)
  File "/opt/py3/lib/python3.6/site-packages/rest_framework/viewsets.py", line 103, in view
    return self.dispatch(request, *args, **kwargs)
  File "/opt/py3/lib/python3.6/site-packages/rest_framework/views.py", line 483, in dispatch
    response = self.handle_exception(exc)
  File "/opt/py3/lib/python3.6/site-packages/rest_framework/views.py", line 443, in handle_exception
    self.raise_uncaught_exception(exc)
  File "/opt/py3/lib/python3.6/site-packages/rest_framework/views.py", line 480, in dispatch
    response = handler(request, *args, **kwargs)
  File "/opt/py3/lib/python3.6/site-packages/rest_framework/mixins.py", line 48, in list
    return Response(serializer.data)
  File "/opt/py3/lib/python3.6/site-packages/rest_framework/serializers.py", line 765, in data
    ret = super(ListSerializer, self).data
  File "/opt/py3/lib/python3.6/site-packages/rest_framework/serializers.py", line 262, in data
    self._data = self.to_representation(self.instance)
  File "/opt/py3/lib/python3.6/site-packages/rest_framework/serializers.py", line 683, in to_representation
    self.child.to_representation(item) for item in iterable
  File "/opt/py3/lib/python3.6/site-packages/django/db/models/query.py", line 268, in __iter__
    self._fetch_all()
  File "/opt/py3/lib/python3.6/site-packages/django/db/models/query.py", line 1186, in _fetch_all
    self._result_cache = list(self._iterable_class(self))
  File "/opt/py3/lib/python3.6/site-packages/django/db/models/query.py", line 63, in __iter__
    for row in compiler.results_iter(results):
  File "/opt/py3/lib/python3.6/site-packages/django/db/models/sql/compiler.py", line 1009, in apply_converters
    value = converter(value, expression, connection)
  File "/opt/py3/lib/python3.6/site-packages/django/db/backends/mysql/operations.py", line 257, in convert_uuidfield_value
    value = uuid.UUID(value)
  File "/usr/local/lib/python3.6/uuid.py", line 140, in __init__
    raise ValueError('badly formed hexadecimal UUID string')
ValueError: badly formed hexadecimal UUID string
2019-02-22 16:19:23 [log ERROR] Internal Server Error: /api/dbaudits/v1/mongosubmit/
Traceback (most recent call last):
  File "/opt/py3/lib/python3.6/site-packages/django/core/handlers/exception.py", line 34, in inner
    response = get_response(request)
  File "/opt/py3/lib/python3.6/site-packages/django/core/handlers/base.py", line 126, in _get_response
    response = self.process_exception_by_middleware(e, request)
  File "/opt/py3/lib/python3.6/site-packages/django/core/handlers/base.py", line 124, in _get_response
    response = wrapped_callback(request, *callback_args, **callback_kwargs)
  File "/usr/local/lib/python3.6/contextlib.py", line 53, in inner
    return func(*args, **kwds)
  File "/opt/py3/lib/python3.6/site-packages/django/views/decorators/csrf.py", line 54, in wrapped_view
    return view_func(*args, **kwargs)
  File "/opt/py3/lib/python3.6/site-packages/rest_framework/viewsets.py", line 103, in view
    return self.dispatch(request, *args, **kwargs)
  File "/opt/py3/lib/python3.6/site-packages/rest_framework/views.py", line 483, in dispatch
    response = self.handle_exception(exc)
  File "/opt/py3/lib/python3.6/site-packages/rest_framework/views.py", line 443, in handle_exception
    self.raise_uncaught_exception(exc)
  File "/opt/py3/lib/python3.6/site-packages/rest_framework/views.py", line 480, in dispatch
    response = handler(request, *args, **kwargs)
  File "/opt/py3/lib/python3.6/site-packages/rest_framework/mixins.py", line 48, in list
    return Response(serializer.data)
  File "/opt/py3/lib/python3.6/site-packages/rest_framework/serializers.py", line 765, in data
    ret = super(ListSerializer, self).data
  File "/opt/py3/lib/python3.6/site-packages/rest_framework/serializers.py", line 262, in data
    self._data = self.to_representation(self.instance)
  File "/opt/py3/lib/python3.6/site-packages/rest_framework/serializers.py", line 683, in to_representation
    self.child.to_representation(item) for item in iterable
  File "/opt/py3/lib/python3.6/site-packages/django/db/models/query.py", line 268, in __iter__
    self._fetch_all()
  File "/opt/py3/lib/python3.6/site-packages/django/db/models/query.py", line 1186, in _fetch_all
    self._result_cache = list(self._iterable_class(self))
  File "/opt/py3/lib/python3.6/site-packages/django/db/models/query.py", line 63, in __iter__
    for row in compiler.results_iter(results):
  File "/opt/py3/lib/python3.6/site-packages/django/db/models/sql/compiler.py", line 1009, in apply_converters
    value = converter(value, expression, connection)
  File "/opt/py3/lib/python3.6/site-packages/django/db/backends/mysql/operations.py", line 257, in convert_uuidfield_value
    value = uuid.UUID(value)
  File "/usr/local/lib/python3.6/uuid.py", line 140, in __init__
    raise ValueError('badly formed hexadecimal UUID string')
ValueError: badly formed hexadecimal UUID string
2019-02-22 16:19:27 [log ERROR] Internal Server Error: /api/dbaudits/v1/mongosubmit/
Traceback (most recent call last):
  File "/opt/py3/lib/python3.6/site-packages/django/core/handlers/exception.py", line 34, in inner
    response = get_response(request)
  File "/opt/py3/lib/python3.6/site-packages/django/core/handlers/base.py", line 126, in _get_response
    response = self.process_exception_by_middleware(e, request)
  File "/opt/py3/lib/python3.6/site-packages/django/core/handlers/base.py", line 124, in _get_response
    response = wrapped_callback(request, *callback_args, **callback_kwargs)
  File "/usr/local/lib/python3.6/contextlib.py", line 53, in inner
    return func(*args, **kwds)
  File "/opt/py3/lib/python3.6/site-packages/django/views/decorators/csrf.py", line 54, in wrapped_view
    return view_func(*args, **kwargs)
  File "/opt/py3/lib/python3.6/site-packages/rest_framework/viewsets.py", line 103, in view
    return self.dispatch(request, *args, **kwargs)
  File "/opt/py3/lib/python3.6/site-packages/rest_framework/views.py", line 483, in dispatch
    response = self.handle_exception(exc)
  File "/opt/py3/lib/python3.6/site-packages/rest_framework/views.py", line 443, in handle_exception
    self.raise_uncaught_exception(exc)
  File "/opt/py3/lib/python3.6/site-packages/rest_framework/views.py", line 480, in dispatch
    response = handler(request, *args, **kwargs)
  File "/opt/py3/lib/python3.6/site-packages/rest_framework/mixins.py", line 48, in list
    return Response(serializer.data)
  File "/opt/py3/lib/python3.6/site-packages/rest_framework/serializers.py", line 765, in data
    ret = super(ListSerializer, self).data
  File "/opt/py3/lib/python3.6/site-packages/rest_framework/serializers.py", line 262, in data
    self._data = self.to_representation(self.instance)
  File "/opt/py3/lib/python3.6/site-packages/rest_framework/serializers.py", line 683, in to_representation
    self.child.to_representation(item) for item in iterable
  File "/opt/py3/lib/python3.6/site-packages/django/db/models/query.py", line 268, in __iter__
    self._fetch_all()
  File "/opt/py3/lib/python3.6/site-packages/django/db/models/query.py", line 1186, in _fetch_all
    self._result_cache = list(self._iterable_class(self))
  File "/opt/py3/lib/python3.6/site-packages/django/db/models/query.py", line 63, in __iter__
    for row in compiler.results_iter(results):
  File "/opt/py3/lib/python3.6/site-packages/django/db/models/sql/compiler.py", line 1009, in apply_converters
    value = converter(value, expression, connection)
  File "/opt/py3/lib/python3.6/site-packages/django/db/backends/mysql/operations.py", line 257, in convert_uuidfield_value
    value = uuid.UUID(value)
  File "/usr/local/lib/python3.6/uuid.py", line 140, in __init__
    raise ValueError('badly formed hexadecimal UUID string')
ValueError: badly formed hexadecimal UUID string
2019-02-22 16:19:38 [log ERROR] Internal Server Error: /api/dbaudits/v1/mongosubmit/
Traceback (most recent call last):
  File "/opt/py3/lib/python3.6/site-packages/django/core/handlers/exception.py", line 34, in inner
    response = get_response(request)
  File "/opt/py3/lib/python3.6/site-packages/django/core/handlers/base.py", line 126, in _get_response
    response = self.process_exception_by_middleware(e, request)
  File "/opt/py3/lib/python3.6/site-packages/django/core/handlers/base.py", line 124, in _get_response
    response = wrapped_callback(request, *callback_args, **callback_kwargs)
  File "/usr/local/lib/python3.6/contextlib.py", line 53, in inner
    return func(*args, **kwds)
  File "/opt/py3/lib/python3.6/site-packages/django/views/decorators/csrf.py", line 54, in wrapped_view
    return view_func(*args, **kwargs)
  File "/opt/py3/lib/python3.6/site-packages/rest_framework/viewsets.py", line 103, in view
    return self.dispatch(request, *args, **kwargs)
  File "/opt/py3/lib/python3.6/site-packages/rest_framework/views.py", line 483, in dispatch
    response = self.handle_exception(exc)
  File "/opt/py3/lib/python3.6/site-packages/rest_framework/views.py", line 443, in handle_exception
    self.raise_uncaught_exception(exc)
  File "/opt/py3/lib/python3.6/site-packages/rest_framework/views.py", line 480, in dispatch
    response = handler(request, *args, **kwargs)
  File "/opt/py3/lib/python3.6/site-packages/rest_framework/mixins.py", line 48, in list
    return Response(serializer.data)
  File "/opt/py3/lib/python3.6/site-packages/rest_framework/serializers.py", line 765, in data
    ret = super(ListSerializer, self).data
  File "/opt/py3/lib/python3.6/site-packages/rest_framework/serializers.py", line 262, in data
    self._data = self.to_representation(self.instance)
  File "/opt/py3/lib/python3.6/site-packages/rest_framework/serializers.py", line 683, in to_representation
    self.child.to_representation(item) for item in iterable
  File "/opt/py3/lib/python3.6/site-packages/django/db/models/query.py", line 268, in __iter__
    self._fetch_all()
  File "/opt/py3/lib/python3.6/site-packages/django/db/models/query.py", line 1186, in _fetch_all
    self._result_cache = list(self._iterable_class(self))
  File "/opt/py3/lib/python3.6/site-packages/django/db/models/query.py", line 63, in __iter__
    for row in compiler.results_iter(results):
  File "/opt/py3/lib/python3.6/site-packages/django/db/models/sql/compiler.py", line 1009, in apply_converters
    value = converter(value, expression, connection)
  File "/opt/py3/lib/python3.6/site-packages/django/db/backends/mysql/operations.py", line 257, in convert_uuidfield_value
    value = uuid.UUID(value)
  File "/usr/local/lib/python3.6/uuid.py", line 140, in __init__
    raise ValueError('badly formed hexadecimal UUID string')
ValueError: badly formed hexadecimal UUID string
2019-02-22 19:22:23 [tasks ERROR] Sending mail error: [Errno -2] Name or service not known
2019-02-25 15:12:22 [tasks ERROR] Sending mail error: [Errno -2] Name or service not known
2019-02-25 15:31:17 [tasks ERROR] Sending mail error: [Errno -2] Name or service not known
2019-02-25 18:11:32 [tasks ERROR] Sending mail error: [Errno -2] Name or service not known
2019-02-26 09:59:47 [log ERROR] Internal Server Error: /users/user/
Traceback (most recent call last):
  File "/opt/py3/lib/python3.6/site-packages/django/core/handlers/exception.py", line 34, in inner
    response = get_response(request)
  File "/opt/py3/lib/python3.6/site-packages/django/core/handlers/base.py", line 156, in _get_response
    response = self.process_exception_by_middleware(e, request)
  File "/opt/py3/lib/python3.6/site-packages/django/core/handlers/base.py", line 154, in _get_response
    response = response.render()
  File "/opt/py3/lib/python3.6/site-packages/django/template/response.py", line 106, in render
    self.content = self.rendered_content
  File "/opt/py3/lib/python3.6/site-packages/django/template/response.py", line 83, in rendered_content
    content = template.render(context, self._request)
  File "/opt/py3/lib/python3.6/site-packages/django/template/backends/django.py", line 61, in render
    return self.template.render(context)
  File "/opt/py3/lib/python3.6/site-packages/django/template/base.py", line 171, in render
    return self._render(context)
  File "/opt/py3/lib/python3.6/site-packages/django/template/base.py", line 163, in _render
    return self.nodelist.render(context)
  File "/opt/py3/lib/python3.6/site-packages/django/template/base.py", line 937, in render
    bit = node.render_annotated(context)
  File "/opt/py3/lib/python3.6/site-packages/django/template/base.py", line 904, in render_annotated
    return self.render(context)
  File "/opt/py3/lib/python3.6/site-packages/django/template/loader_tags.py", line 150, in render
    return compiled_parent._render(context)
  File "/opt/py3/lib/python3.6/site-packages/django/template/base.py", line 163, in _render
    return self.nodelist.render(context)
  File "/opt/py3/lib/python3.6/site-packages/django/template/base.py", line 937, in render
    bit = node.render_annotated(context)
  File "/opt/py3/lib/python3.6/site-packages/django/template/base.py", line 904, in render_annotated
    return self.render(context)
  File "/opt/py3/lib/python3.6/site-packages/django/template/loader_tags.py", line 150, in render
    return compiled_parent._render(context)
  File "/opt/py3/lib/python3.6/site-packages/django/template/base.py", line 163, in _render
    return self.nodelist.render(context)
  File "/opt/py3/lib/python3.6/site-packages/django/template/base.py", line 937, in render
    bit = node.render_annotated(context)
  File "/opt/py3/lib/python3.6/site-packages/django/template/base.py", line 904, in render_annotated
    return self.render(context)
  File "/opt/py3/lib/python3.6/site-packages/django/template/loader_tags.py", line 62, in render
    result = block.nodelist.render(context)
  File "/opt/py3/lib/python3.6/site-packages/django/template/base.py", line 937, in render
    bit = node.render_annotated(context)
  File "/opt/py3/lib/python3.6/site-packages/django/template/base.py", line 904, in render_annotated
    return self.render(context)
  File "/opt/py3/lib/python3.6/site-packages/django/template/defaulttags.py", line 442, in render
    url = reverse(view_name, args=args, kwargs=kwargs, current_app=current_app)
  File "/opt/py3/lib/python3.6/site-packages/django/urls/base.py", line 90, in reverse
    return iri_to_uri(resolver._reverse_with_prefix(view, prefix, *args, **kwargs))
  File "/opt/py3/lib/python3.6/site-packages/django/urls/resolvers.py", line 622, in _reverse_with_prefix
    raise NoReverseMatch(msg)
django.urls.exceptions.NoReverseMatch: Reverse for 'user-list' not found. 'user-list' is not a valid view function or pattern name.
2019-02-26 11:00:02 [log ERROR] Internal Server Error: /users/user/
Traceback (most recent call last):
  File "/opt/py3/lib/python3.6/site-packages/django/core/handlers/exception.py", line 34, in inner
    response = get_response(request)
  File "/opt/py3/lib/python3.6/site-packages/django/core/handlers/base.py", line 156, in _get_response
    response = self.process_exception_by_middleware(e, request)
  File "/opt/py3/lib/python3.6/site-packages/django/core/handlers/base.py", line 154, in _get_response
    response = response.render()
  File "/opt/py3/lib/python3.6/site-packages/django/template/response.py", line 106, in render
    self.content = self.rendered_content
  File "/opt/py3/lib/python3.6/site-packages/django/template/response.py", line 83, in rendered_content
    content = template.render(context, self._request)
  File "/opt/py3/lib/python3.6/site-packages/django/template/backends/django.py", line 61, in render
    return self.template.render(context)
  File "/opt/py3/lib/python3.6/site-packages/django/template/base.py", line 171, in render
    return self._render(context)
  File "/opt/py3/lib/python3.6/site-packages/django/template/base.py", line 163, in _render
    return self.nodelist.render(context)
  File "/opt/py3/lib/python3.6/site-packages/django/template/base.py", line 937, in render
    bit = node.render_annotated(context)
  File "/opt/py3/lib/python3.6/site-packages/django/template/base.py", line 904, in render_annotated
    return self.render(context)
  File "/opt/py3/lib/python3.6/site-packages/django/template/loader_tags.py", line 150, in render
    return compiled_parent._render(context)
  File "/opt/py3/lib/python3.6/site-packages/django/template/base.py", line 163, in _render
    return self.nodelist.render(context)
  File "/opt/py3/lib/python3.6/site-packages/django/template/base.py", line 937, in render
    bit = node.render_annotated(context)
  File "/opt/py3/lib/python3.6/site-packages/django/template/base.py", line 904, in render_annotated
    return self.render(context)
  File "/opt/py3/lib/python3.6/site-packages/django/template/loader_tags.py", line 150, in render
    return compiled_parent._render(context)
  File "/opt/py3/lib/python3.6/site-packages/django/template/base.py", line 163, in _render
    return self.nodelist.render(context)
  File "/opt/py3/lib/python3.6/site-packages/django/template/base.py", line 937, in render
    bit = node.render_annotated(context)
  File "/opt/py3/lib/python3.6/site-packages/django/template/base.py", line 904, in render_annotated
    return self.render(context)
  File "/opt/py3/lib/python3.6/site-packages/django/template/loader_tags.py", line 62, in render
    result = block.nodelist.render(context)
  File "/opt/py3/lib/python3.6/site-packages/django/template/base.py", line 937, in render
    bit = node.render_annotated(context)
  File "/opt/py3/lib/python3.6/site-packages/django/template/base.py", line 904, in render_annotated
    return self.render(context)
  File "/opt/py3/lib/python3.6/site-packages/django/template/defaulttags.py", line 442, in render
    url = reverse(view_name, args=args, kwargs=kwargs, current_app=current_app)
  File "/opt/py3/lib/python3.6/site-packages/django/urls/base.py", line 90, in reverse
    return iri_to_uri(resolver._reverse_with_prefix(view, prefix, *args, **kwargs))
  File "/opt/py3/lib/python3.6/site-packages/django/urls/resolvers.py", line 622, in _reverse_with_prefix
    raise NoReverseMatch(msg)
django.urls.exceptions.NoReverseMatch: Reverse for 'user-list' not found. 'user-list' is not a valid view function or pattern name.
2019-02-26 11:00:27 [log ERROR] Internal Server Error: /users/user/
Traceback (most recent call last):
  File "/opt/py3/lib/python3.6/site-packages/django/core/handlers/exception.py", line 34, in inner
    response = get_response(request)
  File "/opt/py3/lib/python3.6/site-packages/django/core/handlers/base.py", line 156, in _get_response
    response = self.process_exception_by_middleware(e, request)
  File "/opt/py3/lib/python3.6/site-packages/django/core/handlers/base.py", line 154, in _get_response
    response = response.render()
  File "/opt/py3/lib/python3.6/site-packages/django/template/response.py", line 106, in render
    self.content = self.rendered_content
  File "/opt/py3/lib/python3.6/site-packages/django/template/response.py", line 83, in rendered_content
    content = template.render(context, self._request)
  File "/opt/py3/lib/python3.6/site-packages/django/template/backends/django.py", line 61, in render
    return self.template.render(context)
  File "/opt/py3/lib/python3.6/site-packages/django/template/base.py", line 171, in render
    return self._render(context)
  File "/opt/py3/lib/python3.6/site-packages/django/template/base.py", line 163, in _render
    return self.nodelist.render(context)
  File "/opt/py3/lib/python3.6/site-packages/django/template/base.py", line 937, in render
    bit = node.render_annotated(context)
  File "/opt/py3/lib/python3.6/site-packages/django/template/base.py", line 904, in render_annotated
    return self.render(context)
  File "/opt/py3/lib/python3.6/site-packages/django/template/loader_tags.py", line 150, in render
    return compiled_parent._render(context)
  File "/opt/py3/lib/python3.6/site-packages/django/template/base.py", line 163, in _render
    return self.nodelist.render(context)
  File "/opt/py3/lib/python3.6/site-packages/django/template/base.py", line 937, in render
    bit = node.render_annotated(context)
  File "/opt/py3/lib/python3.6/site-packages/django/template/base.py", line 904, in render_annotated
    return self.render(context)
  File "/opt/py3/lib/python3.6/site-packages/django/template/loader_tags.py", line 150, in render
    return compiled_parent._render(context)
  File "/opt/py3/lib/python3.6/site-packages/django/template/base.py", line 163, in _render
    return self.nodelist.render(context)
  File "/opt/py3/lib/python3.6/site-packages/django/template/base.py", line 937, in render
    bit = node.render_annotated(context)
  File "/opt/py3/lib/python3.6/site-packages/django/template/base.py", line 904, in render_annotated
    return self.render(context)
  File "/opt/py3/lib/python3.6/site-packages/django/template/loader_tags.py", line 62, in render
    result = block.nodelist.render(context)
  File "/opt/py3/lib/python3.6/site-packages/django/template/base.py", line 937, in render
    bit = node.render_annotated(context)
  File "/opt/py3/lib/python3.6/site-packages/django/template/base.py", line 904, in render_annotated
    return self.render(context)
  File "/opt/py3/lib/python3.6/site-packages/django/template/defaulttags.py", line 442, in render
    url = reverse(view_name, args=args, kwargs=kwargs, current_app=current_app)
  File "/opt/py3/lib/python3.6/site-packages/django/urls/base.py", line 90, in reverse
    return iri_to_uri(resolver._reverse_with_prefix(view, prefix, *args, **kwargs))
  File "/opt/py3/lib/python3.6/site-packages/django/urls/resolvers.py", line 622, in _reverse_with_prefix
    raise NoReverseMatch(msg)
django.urls.exceptions.NoReverseMatch: Reverse for 'user-list' not found. 'user-list' is not a valid view function or pattern name.
2019-02-26 11:00:53 [log ERROR] Internal Server Error: /users/user/
Traceback (most recent call last):
  File "/opt/py3/lib/python3.6/site-packages/django/core/handlers/exception.py", line 34, in inner
    response = get_response(request)
  File "/opt/py3/lib/python3.6/site-packages/django/core/handlers/base.py", line 156, in _get_response
    response = self.process_exception_by_middleware(e, request)
  File "/opt/py3/lib/python3.6/site-packages/django/core/handlers/base.py", line 154, in _get_response
    response = response.render()
  File "/opt/py3/lib/python3.6/site-packages/django/template/response.py", line 106, in render
    self.content = self.rendered_content
  File "/opt/py3/lib/python3.6/site-packages/django/template/response.py", line 83, in rendered_content
    content = template.render(context, self._request)
  File "/opt/py3/lib/python3.6/site-packages/django/template/backends/django.py", line 61, in render
    return self.template.render(context)
  File "/opt/py3/lib/python3.6/site-packages/django/template/base.py", line 171, in render
    return self._render(context)
  File "/opt/py3/lib/python3.6/site-packages/django/template/base.py", line 163, in _render
    return self.nodelist.render(context)
  File "/opt/py3/lib/python3.6/site-packages/django/template/base.py", line 937, in render
    bit = node.render_annotated(context)
  File "/opt/py3/lib/python3.6/site-packages/django/template/base.py", line 904, in render_annotated
    return self.render(context)
  File "/opt/py3/lib/python3.6/site-packages/django/template/loader_tags.py", line 150, in render
    return compiled_parent._render(context)
  File "/opt/py3/lib/python3.6/site-packages/django/template/base.py", line 163, in _render
    return self.nodelist.render(context)
  File "/opt/py3/lib/python3.6/site-packages/django/template/base.py", line 937, in render
    bit = node.render_annotated(context)
  File "/opt/py3/lib/python3.6/site-packages/django/template/base.py", line 904, in render_annotated
    return self.render(context)
  File "/opt/py3/lib/python3.6/site-packages/django/template/loader_tags.py", line 150, in render
    return compiled_parent._render(context)
  File "/opt/py3/lib/python3.6/site-packages/django/template/base.py", line 163, in _render
    return self.nodelist.render(context)
  File "/opt/py3/lib/python3.6/site-packages/django/template/base.py", line 937, in render
    bit = node.render_annotated(context)
  File "/opt/py3/lib/python3.6/site-packages/django/template/base.py", line 904, in render_annotated
    return self.render(context)
  File "/opt/py3/lib/python3.6/site-packages/django/template/loader_tags.py", line 62, in render
    result = block.nodelist.render(context)
  File "/opt/py3/lib/python3.6/site-packages/django/template/base.py", line 937, in render
    bit = node.render_annotated(context)
  File "/opt/py3/lib/python3.6/site-packages/django/template/base.py", line 904, in render_annotated
    return self.render(context)
  File "/opt/py3/lib/python3.6/site-packages/django/template/defaulttags.py", line 442, in render
    url = reverse(view_name, args=args, kwargs=kwargs, current_app=current_app)
  File "/opt/py3/lib/python3.6/site-packages/django/urls/base.py", line 90, in reverse
    return iri_to_uri(resolver._reverse_with_prefix(view, prefix, *args, **kwargs))
  File "/opt/py3/lib/python3.6/site-packages/django/urls/resolvers.py", line 622, in _reverse_with_prefix
    raise NoReverseMatch(msg)
django.urls.exceptions.NoReverseMatch: Reverse for 'user-list' not found. 'user-list' is not a valid view function or pattern name.
2019-02-26 11:01:14 [tasks ERROR] Sending mail error: [Errno -2] Name or service not known
2019-02-26 11:01:14 [log ERROR] Internal Server Error: /users/user/
Traceback (most recent call last):
  File "/opt/py3/lib/python3.6/site-packages/django/core/handlers/exception.py", line 34, in inner
    response = get_response(request)
  File "/opt/py3/lib/python3.6/site-packages/django/core/handlers/base.py", line 156, in _get_response
    response = self.process_exception_by_middleware(e, request)
  File "/opt/py3/lib/python3.6/site-packages/django/core/handlers/base.py", line 154, in _get_response
    response = response.render()
  File "/opt/py3/lib/python3.6/site-packages/django/template/response.py", line 106, in render
    self.content = self.rendered_content
  File "/opt/py3/lib/python3.6/site-packages/django/template/response.py", line 83, in rendered_content
    content = template.render(context, self._request)
  File "/opt/py3/lib/python3.6/site-packages/django/template/backends/django.py", line 61, in render
    return self.template.render(context)
  File "/opt/py3/lib/python3.6/site-packages/django/template/base.py", line 171, in render
    return self._render(context)
  File "/opt/py3/lib/python3.6/site-packages/django/template/base.py", line 163, in _render
    return self.nodelist.render(context)
  File "/opt/py3/lib/python3.6/site-packages/django/template/base.py", line 937, in render
    bit = node.render_annotated(context)
  File "/opt/py3/lib/python3.6/site-packages/django/template/base.py", line 904, in render_annotated
    return self.render(context)
  File "/opt/py3/lib/python3.6/site-packages/django/template/loader_tags.py", line 150, in render
    return compiled_parent._render(context)
  File "/opt/py3/lib/python3.6/site-packages/django/template/base.py", line 163, in _render
    return self.nodelist.render(context)
  File "/opt/py3/lib/python3.6/site-packages/django/template/base.py", line 937, in render
    bit = node.render_annotated(context)
  File "/opt/py3/lib/python3.6/site-packages/django/template/base.py", line 904, in render_annotated
    return self.render(context)
  File "/opt/py3/lib/python3.6/site-packages/django/template/loader_tags.py", line 150, in render
    return compiled_parent._render(context)
  File "/opt/py3/lib/python3.6/site-packages/django/template/base.py", line 163, in _render
    return self.nodelist.render(context)
  File "/opt/py3/lib/python3.6/site-packages/django/template/base.py", line 937, in render
    bit = node.render_annotated(context)
  File "/opt/py3/lib/python3.6/site-packages/django/template/base.py", line 904, in render_annotated
    return self.render(context)
  File "/opt/py3/lib/python3.6/site-packages/django/template/loader_tags.py", line 62, in render
    result = block.nodelist.render(context)
  File "/opt/py3/lib/python3.6/site-packages/django/template/base.py", line 937, in render
    bit = node.render_annotated(context)
  File "/opt/py3/lib/python3.6/site-packages/django/template/base.py", line 904, in render_annotated
    return self.render(context)
  File "/opt/py3/lib/python3.6/site-packages/django/template/defaulttags.py", line 442, in render
    url = reverse(view_name, args=args, kwargs=kwargs, current_app=current_app)
  File "/opt/py3/lib/python3.6/site-packages/django/urls/base.py", line 90, in reverse
    return iri_to_uri(resolver._reverse_with_prefix(view, prefix, *args, **kwargs))
  File "/opt/py3/lib/python3.6/site-packages/django/urls/resolvers.py", line 622, in _reverse_with_prefix
    raise NoReverseMatch(msg)
django.urls.exceptions.NoReverseMatch: Reverse for 'user-list' not found. 'user-list' is not a valid view function or pattern name.
2019-02-26 11:07:45 [log ERROR] Internal Server Error: /users/user/
Traceback (most recent call last):
  File "/opt/py3/lib/python3.6/site-packages/django/core/handlers/exception.py", line 34, in inner
    response = get_response(request)
  File "/opt/py3/lib/python3.6/site-packages/django/core/handlers/base.py", line 156, in _get_response
    response = self.process_exception_by_middleware(e, request)
  File "/opt/py3/lib/python3.6/site-packages/django/core/handlers/base.py", line 154, in _get_response
    response = response.render()
  File "/opt/py3/lib/python3.6/site-packages/django/template/response.py", line 106, in render
    self.content = self.rendered_content
  File "/opt/py3/lib/python3.6/site-packages/django/template/response.py", line 83, in rendered_content
    content = template.render(context, self._request)
  File "/opt/py3/lib/python3.6/site-packages/django/template/backends/django.py", line 61, in render
    return self.template.render(context)
  File "/opt/py3/lib/python3.6/site-packages/django/template/base.py", line 171, in render
    return self._render(context)
  File "/opt/py3/lib/python3.6/site-packages/django/template/base.py", line 163, in _render
    return self.nodelist.render(context)
  File "/opt/py3/lib/python3.6/site-packages/django/template/base.py", line 937, in render
    bit = node.render_annotated(context)
  File "/opt/py3/lib/python3.6/site-packages/django/template/base.py", line 904, in render_annotated
    return self.render(context)
  File "/opt/py3/lib/python3.6/site-packages/django/template/loader_tags.py", line 150, in render
    return compiled_parent._render(context)
  File "/opt/py3/lib/python3.6/site-packages/django/template/base.py", line 163, in _render
    return self.nodelist.render(context)
  File "/opt/py3/lib/python3.6/site-packages/django/template/base.py", line 937, in render
    bit = node.render_annotated(context)
  File "/opt/py3/lib/python3.6/site-packages/django/template/base.py", line 904, in render_annotated
    return self.render(context)
  File "/opt/py3/lib/python3.6/site-packages/django/template/loader_tags.py", line 150, in render
    return compiled_parent._render(context)
  File "/opt/py3/lib/python3.6/site-packages/django/template/base.py", line 163, in _render
    return self.nodelist.render(context)
  File "/opt/py3/lib/python3.6/site-packages/django/template/base.py", line 937, in render
    bit = node.render_annotated(context)
  File "/opt/py3/lib/python3.6/site-packages/django/template/base.py", line 904, in render_annotated
    return self.render(context)
  File "/opt/py3/lib/python3.6/site-packages/django/template/loader_tags.py", line 62, in render
    result = block.nodelist.render(context)
  File "/opt/py3/lib/python3.6/site-packages/django/template/base.py", line 937, in render
    bit = node.render_annotated(context)
  File "/opt/py3/lib/python3.6/site-packages/django/template/base.py", line 904, in render_annotated
    return self.render(context)
  File "/opt/py3/lib/python3.6/site-packages/django/template/defaulttags.py", line 442, in render
    url = reverse(view_name, args=args, kwargs=kwargs, current_app=current_app)
  File "/opt/py3/lib/python3.6/site-packages/django/urls/base.py", line 90, in reverse
    return iri_to_uri(resolver._reverse_with_prefix(view, prefix, *args, **kwargs))
  File "/opt/py3/lib/python3.6/site-packages/django/urls/resolvers.py", line 622, in _reverse_with_prefix
    raise NoReverseMatch(msg)
django.urls.exceptions.NoReverseMatch: Reverse for 'user-list' not found. 'user-list' is not a valid view function or pattern name.
2019-02-26 11:08:28 [log ERROR] Internal Server Error: /users/user/
Traceback (most recent call last):
  File "/opt/py3/lib/python3.6/site-packages/django/core/handlers/exception.py", line 34, in inner
    response = get_response(request)
  File "/opt/py3/lib/python3.6/site-packages/django/core/handlers/base.py", line 156, in _get_response
    response = self.process_exception_by_middleware(e, request)
  File "/opt/py3/lib/python3.6/site-packages/django/core/handlers/base.py", line 154, in _get_response
    response = response.render()
  File "/opt/py3/lib/python3.6/site-packages/django/template/response.py", line 106, in render
    self.content = self.rendered_content
  File "/opt/py3/lib/python3.6/site-packages/django/template/response.py", line 83, in rendered_content
    content = template.render(context, self._request)
  File "/opt/py3/lib/python3.6/site-packages/django/template/backends/django.py", line 61, in render
    return self.template.render(context)
  File "/opt/py3/lib/python3.6/site-packages/django/template/base.py", line 171, in render
    return self._render(context)
  File "/opt/py3/lib/python3.6/site-packages/django/template/base.py", line 163, in _render
    return self.nodelist.render(context)
  File "/opt/py3/lib/python3.6/site-packages/django/template/base.py", line 937, in render
    bit = node.render_annotated(context)
  File "/opt/py3/lib/python3.6/site-packages/django/template/base.py", line 904, in render_annotated
    return self.render(context)
  File "/opt/py3/lib/python3.6/site-packages/django/template/loader_tags.py", line 150, in render
    return compiled_parent._render(context)
  File "/opt/py3/lib/python3.6/site-packages/django/template/base.py", line 163, in _render
    return self.nodelist.render(context)
  File "/opt/py3/lib/python3.6/site-packages/django/template/base.py", line 937, in render
    bit = node.render_annotated(context)
  File "/opt/py3/lib/python3.6/site-packages/django/template/base.py", line 904, in render_annotated
    return self.render(context)
  File "/opt/py3/lib/python3.6/site-packages/django/template/loader_tags.py", line 150, in render
    return compiled_parent._render(context)
  File "/opt/py3/lib/python3.6/site-packages/django/template/base.py", line 163, in _render
    return self.nodelist.render(context)
  File "/opt/py3/lib/python3.6/site-packages/django/template/base.py", line 937, in render
    bit = node.render_annotated(context)
  File "/opt/py3/lib/python3.6/site-packages/django/template/base.py", line 904, in render_annotated
    return self.render(context)
  File "/opt/py3/lib/python3.6/site-packages/django/template/loader_tags.py", line 62, in render
    result = block.nodelist.render(context)
  File "/opt/py3/lib/python3.6/site-packages/django/template/base.py", line 937, in render
    bit = node.render_annotated(context)
  File "/opt/py3/lib/python3.6/site-packages/django/template/base.py", line 904, in render_annotated
    return self.render(context)
  File "/opt/py3/lib/python3.6/site-packages/django/template/defaulttags.py", line 442, in render
    url = reverse(view_name, args=args, kwargs=kwargs, current_app=current_app)
  File "/opt/py3/lib/python3.6/site-packages/django/urls/base.py", line 90, in reverse
    return iri_to_uri(resolver._reverse_with_prefix(view, prefix, *args, **kwargs))
  File "/opt/py3/lib/python3.6/site-packages/django/urls/resolvers.py", line 622, in _reverse_with_prefix
    raise NoReverseMatch(msg)
django.urls.exceptions.NoReverseMatch: Reverse for 'user-list' not found. 'user-list' is not a valid view function or pattern name.
2019-02-26 15:50:00 [log ERROR] Internal Server Error: /dbaudits/mongo-submit
Traceback (most recent call last):
  File "/opt/py3/lib/python3.6/site-packages/django/views/generic/edit.py", line 116, in get_success_url
    url = self.object.get_absolute_url()
AttributeError: 'MongoSubmit' object has no attribute 'get_absolute_url'

During handling of the above exception, another exception occurred:

Traceback (most recent call last):
  File "/opt/py3/lib/python3.6/site-packages/django/core/handlers/exception.py", line 34, in inner
    response = get_response(request)
  File "/opt/py3/lib/python3.6/site-packages/django/core/handlers/base.py", line 126, in _get_response
    response = self.process_exception_by_middleware(e, request)
  File "/opt/py3/lib/python3.6/site-packages/django/core/handlers/base.py", line 124, in _get_response
    response = wrapped_callback(request, *callback_args, **callback_kwargs)
  File "/usr/local/lib/python3.6/contextlib.py", line 53, in inner
    return func(*args, **kwds)
  File "/opt/py3/lib/python3.6/site-packages/django/views/generic/base.py", line 68, in view
    return self.dispatch(request, *args, **kwargs)
  File "/opt/jumpserver/apps/common/permissions.py", line 93, in dispatch
    return super().dispatch(request, *args, **kwargs)
  File "/opt/py3/lib/python3.6/site-packages/django/contrib/auth/mixins.py", line 109, in dispatch
    return super().dispatch(request, *args, **kwargs)
  File "/opt/py3/lib/python3.6/site-packages/django/views/generic/base.py", line 88, in dispatch
    return handler(request, *args, **kwargs)
  File "/opt/py3/lib/python3.6/site-packages/django/views/generic/edit.py", line 172, in post
    return super().post(request, *args, **kwargs)
  File "/opt/py3/lib/python3.6/site-packages/django/views/generic/edit.py", line 142, in post
    return self.form_valid(form)
  File "/opt/py3/lib/python3.6/site-packages/django/contrib/messages/views.py", line 11, in form_valid
    response = super().form_valid(form)
  File "/opt/py3/lib/python3.6/site-packages/django/views/generic/edit.py", line 126, in form_valid
    return super().form_valid(form)
  File "/opt/py3/lib/python3.6/site-packages/django/views/generic/edit.py", line 57, in form_valid
    return HttpResponseRedirect(self.get_success_url())
  File "/opt/py3/lib/python3.6/site-packages/django/views/generic/edit.py", line 119, in get_success_url
    "No URL to redirect to.  Either provide a url or define"
django.core.exceptions.ImproperlyConfigured: No URL to redirect to.  Either provide a url or define a get_absolute_url method on the Model.
2019-02-26 17:32:04 [log ERROR] Internal Server Error: /dbaudits/mongo-submit
Traceback (most recent call last):
  File "/opt/py3/lib/python3.6/site-packages/django/core/handlers/exception.py", line 34, in inner
    response = get_response(request)
  File "/opt/py3/lib/python3.6/site-packages/django/core/handlers/base.py", line 126, in _get_response
    response = self.process_exception_by_middleware(e, request)
  File "/opt/py3/lib/python3.6/site-packages/django/core/handlers/base.py", line 124, in _get_response
    response = wrapped_callback(request, *callback_args, **callback_kwargs)
  File "/usr/local/lib/python3.6/contextlib.py", line 53, in inner
    return func(*args, **kwds)
  File "/opt/py3/lib/python3.6/site-packages/django/views/generic/base.py", line 68, in view
    return self.dispatch(request, *args, **kwargs)
  File "/opt/jumpserver/apps/common/permissions.py", line 93, in dispatch
    return super().dispatch(request, *args, **kwargs)
  File "/opt/py3/lib/python3.6/site-packages/django/contrib/auth/mixins.py", line 109, in dispatch
    return super().dispatch(request, *args, **kwargs)
  File "/opt/py3/lib/python3.6/site-packages/django/views/generic/base.py", line 88, in dispatch
    return handler(request, *args, **kwargs)
  File "/opt/py3/lib/python3.6/site-packages/django/views/generic/edit.py", line 172, in post
    return super().post(request, *args, **kwargs)
  File "/opt/py3/lib/python3.6/site-packages/django/views/generic/edit.py", line 142, in post
    return self.form_valid(form)
  File "/opt/py3/lib/python3.6/site-packages/django/contrib/messages/views.py", line 11, in form_valid
    response = super().form_valid(form)
  File "/opt/py3/lib/python3.6/site-packages/django/views/generic/edit.py", line 125, in form_valid
    self.object = form.save()
  File "/opt/jumpserver/apps/dbaudits/forms.py", line 26, in save
    MngoSubmit.save()
  File "/opt/py3/lib/python3.6/site-packages/django/db/models/base.py", line 718, in save
    force_update=force_update, update_fields=update_fields)
  File "/opt/py3/lib/python3.6/site-packages/django/db/models/base.py", line 748, in save_base
    updated = self._save_table(raw, cls, force_insert, force_update, using, update_fields)
  File "/opt/py3/lib/python3.6/site-packages/django/db/models/base.py", line 812, in _save_table
    forced_update)
  File "/opt/py3/lib/python3.6/site-packages/django/db/models/base.py", line 861, in _do_update
    return filtered._update(values) > 0
  File "/opt/py3/lib/python3.6/site-packages/django/db/models/query.py", line 712, in _update
    return query.get_compiler(self.db).execute_sql(CURSOR)
  File "/opt/py3/lib/python3.6/site-packages/django/db/models/sql/compiler.py", line 1383, in execute_sql
    cursor = super().execute_sql(result_type)
  File "/opt/py3/lib/python3.6/site-packages/django/db/models/sql/compiler.py", line 1052, in execute_sql
    sql, params = self.as_sql()
  File "/opt/py3/lib/python3.6/site-packages/django/db/models/sql/compiler.py", line 1349, in as_sql
    val = field.get_db_prep_save(val, connection=self.connection)
  File "/opt/py3/lib/python3.6/site-packages/django/db/models/fields/__init__.py", line 790, in get_db_prep_save
    return self.get_db_prep_value(value, connection=connection, prepared=False)
  File "/opt/py3/lib/python3.6/site-packages/django/db/models/fields/__init__.py", line 785, in get_db_prep_value
    value = self.get_prep_value(value)
  File "/opt/py3/lib/python3.6/site-packages/django/db/models/fields/__init__.py", line 1018, in get_prep_value
    return self.to_python(value)
  File "/opt/py3/lib/python3.6/site-packages/django/db/models/fields/__init__.py", line 1011, in to_python
    params={'value': value},
django.core.exceptions.ValidationError: ['’2‘ 必须为 True 或者 False。']
2019-03-07 10:50:58 [log ERROR] Internal Server Error: /dbaudits/mongo-list
Traceback (most recent call last):
  File "/opt/py3/lib/python3.6/site-packages/django/core/handlers/exception.py", line 34, in inner
    response = get_response(request)
  File "/opt/py3/lib/python3.6/site-packages/django/core/handlers/base.py", line 156, in _get_response
    response = self.process_exception_by_middleware(e, request)
  File "/opt/py3/lib/python3.6/site-packages/django/core/handlers/base.py", line 154, in _get_response
    response = response.render()
  File "/opt/py3/lib/python3.6/site-packages/django/template/response.py", line 106, in render
    self.content = self.rendered_content
  File "/opt/py3/lib/python3.6/site-packages/django/template/response.py", line 81, in rendered_content
    template = self.resolve_template(self.template_name)
  File "/opt/py3/lib/python3.6/site-packages/django/template/response.py", line 63, in resolve_template
    return select_template(template, using=self.using)
  File "/opt/py3/lib/python3.6/site-packages/django/template/loader.py", line 47, in select_template
    raise TemplateDoesNotExist(', '.join(template_name_list), chain=chain)
django.template.exceptions.TemplateDoesNotExist: mongo/mongo_list.html
2019-03-07 10:51:00 [log ERROR] Internal Server Error: /dbaudits/mongo-list
Traceback (most recent call last):
  File "/opt/py3/lib/python3.6/site-packages/django/core/handlers/exception.py", line 34, in inner
    response = get_response(request)
  File "/opt/py3/lib/python3.6/site-packages/django/core/handlers/base.py", line 156, in _get_response
    response = self.process_exception_by_middleware(e, request)
  File "/opt/py3/lib/python3.6/site-packages/django/core/handlers/base.py", line 154, in _get_response
    response = response.render()
  File "/opt/py3/lib/python3.6/site-packages/django/template/response.py", line 106, in render
    self.content = self.rendered_content
  File "/opt/py3/lib/python3.6/site-packages/django/template/response.py", line 81, in rendered_content
    template = self.resolve_template(self.template_name)
  File "/opt/py3/lib/python3.6/site-packages/django/template/response.py", line 63, in resolve_template
    return select_template(template, using=self.using)
  File "/opt/py3/lib/python3.6/site-packages/django/template/loader.py", line 47, in select_template
    raise TemplateDoesNotExist(', '.join(template_name_list), chain=chain)
django.template.exceptions.TemplateDoesNotExist: mongo/mongo_list.html
2019-03-07 10:51:13 [log ERROR] Internal Server Error: /dbaudits/mongo-list
Traceback (most recent call last):
  File "/opt/py3/lib/python3.6/site-packages/django/core/handlers/exception.py", line 34, in inner
    response = get_response(request)
  File "/opt/py3/lib/python3.6/site-packages/django/core/handlers/base.py", line 156, in _get_response
    response = self.process_exception_by_middleware(e, request)
  File "/opt/py3/lib/python3.6/site-packages/django/core/handlers/base.py", line 154, in _get_response
    response = response.render()
  File "/opt/py3/lib/python3.6/site-packages/django/template/response.py", line 106, in render
    self.content = self.rendered_content
  File "/opt/py3/lib/python3.6/site-packages/django/template/response.py", line 81, in rendered_content
    template = self.resolve_template(self.template_name)
  File "/opt/py3/lib/python3.6/site-packages/django/template/response.py", line 63, in resolve_template
    return select_template(template, using=self.using)
  File "/opt/py3/lib/python3.6/site-packages/django/template/loader.py", line 47, in select_template
    raise TemplateDoesNotExist(', '.join(template_name_list), chain=chain)
django.template.exceptions.TemplateDoesNotExist: mongo/mongo_list.html
2019-03-07 10:51:30 [log ERROR] Internal Server Error: /dbaudits/mongo-list
Traceback (most recent call last):
  File "/opt/py3/lib/python3.6/site-packages/django/core/handlers/exception.py", line 34, in inner
    response = get_response(request)
  File "/opt/py3/lib/python3.6/site-packages/django/core/handlers/base.py", line 156, in _get_response
    response = self.process_exception_by_middleware(e, request)
  File "/opt/py3/lib/python3.6/site-packages/django/core/handlers/base.py", line 154, in _get_response
    response = response.render()
  File "/opt/py3/lib/python3.6/site-packages/django/template/response.py", line 106, in render
    self.content = self.rendered_content
  File "/opt/py3/lib/python3.6/site-packages/django/template/response.py", line 81, in rendered_content
    template = self.resolve_template(self.template_name)
  File "/opt/py3/lib/python3.6/site-packages/django/template/response.py", line 63, in resolve_template
    return select_template(template, using=self.using)
  File "/opt/py3/lib/python3.6/site-packages/django/template/loader.py", line 47, in select_template
    raise TemplateDoesNotExist(', '.join(template_name_list), chain=chain)
django.template.exceptions.TemplateDoesNotExist: mongo/mongo_list.html
2019-03-07 10:53:16 [log ERROR] Internal Server Error: /dbaudits/mongo-list
Traceback (most recent call last):
  File "/opt/py3/lib/python3.6/site-packages/django/core/handlers/exception.py", line 34, in inner
    response = get_response(request)
  File "/opt/py3/lib/python3.6/site-packages/django/core/handlers/base.py", line 156, in _get_response
    response = self.process_exception_by_middleware(e, request)
  File "/opt/py3/lib/python3.6/site-packages/django/core/handlers/base.py", line 154, in _get_response
    response = response.render()
  File "/opt/py3/lib/python3.6/site-packages/django/template/response.py", line 106, in render
    self.content = self.rendered_content
  File "/opt/py3/lib/python3.6/site-packages/django/template/response.py", line 81, in rendered_content
    template = self.resolve_template(self.template_name)
  File "/opt/py3/lib/python3.6/site-packages/django/template/response.py", line 63, in resolve_template
    return select_template(template, using=self.using)
  File "/opt/py3/lib/python3.6/site-packages/django/template/loader.py", line 47, in select_template
    raise TemplateDoesNotExist(', '.join(template_name_list), chain=chain)
django.template.exceptions.TemplateDoesNotExist: mongo/mongo_list.html
2019-03-07 10:53:18 [log ERROR] Internal Server Error: /dbaudits/mongo-list
Traceback (most recent call last):
  File "/opt/py3/lib/python3.6/site-packages/django/core/handlers/exception.py", line 34, in inner
    response = get_response(request)
  File "/opt/py3/lib/python3.6/site-packages/django/core/handlers/base.py", line 156, in _get_response
    response = self.process_exception_by_middleware(e, request)
  File "/opt/py3/lib/python3.6/site-packages/django/core/handlers/base.py", line 154, in _get_response
    response = response.render()
  File "/opt/py3/lib/python3.6/site-packages/django/template/response.py", line 106, in render
    self.content = self.rendered_content
  File "/opt/py3/lib/python3.6/site-packages/django/template/response.py", line 81, in rendered_content
    template = self.resolve_template(self.template_name)
  File "/opt/py3/lib/python3.6/site-packages/django/template/response.py", line 63, in resolve_template
    return select_template(template, using=self.using)
  File "/opt/py3/lib/python3.6/site-packages/django/template/loader.py", line 47, in select_template
    raise TemplateDoesNotExist(', '.join(template_name_list), chain=chain)
django.template.exceptions.TemplateDoesNotExist: mongo/mongo_list.html
2019-03-07 10:53:19 [log ERROR] Internal Server Error: /dbaudits/mongo-list
Traceback (most recent call last):
  File "/opt/py3/lib/python3.6/site-packages/django/core/handlers/exception.py", line 34, in inner
    response = get_response(request)
  File "/opt/py3/lib/python3.6/site-packages/django/core/handlers/base.py", line 156, in _get_response
    response = self.process_exception_by_middleware(e, request)
  File "/opt/py3/lib/python3.6/site-packages/django/core/handlers/base.py", line 154, in _get_response
    response = response.render()
  File "/opt/py3/lib/python3.6/site-packages/django/template/response.py", line 106, in render
    self.content = self.rendered_content
  File "/opt/py3/lib/python3.6/site-packages/django/template/response.py", line 81, in rendered_content
    template = self.resolve_template(self.template_name)
  File "/opt/py3/lib/python3.6/site-packages/django/template/response.py", line 63, in resolve_template
    return select_template(template, using=self.using)
  File "/opt/py3/lib/python3.6/site-packages/django/template/loader.py", line 47, in select_template
    raise TemplateDoesNotExist(', '.join(template_name_list), chain=chain)
django.template.exceptions.TemplateDoesNotExist: mongo/mongo_list.html
2019-03-07 10:53:19 [log ERROR] Internal Server Error: /dbaudits/mongo-list
Traceback (most recent call last):
  File "/opt/py3/lib/python3.6/site-packages/django/core/handlers/exception.py", line 34, in inner
    response = get_response(request)
  File "/opt/py3/lib/python3.6/site-packages/django/core/handlers/base.py", line 156, in _get_response
    response = self.process_exception_by_middleware(e, request)
  File "/opt/py3/lib/python3.6/site-packages/django/core/handlers/base.py", line 154, in _get_response
    response = response.render()
  File "/opt/py3/lib/python3.6/site-packages/django/template/response.py", line 106, in render
    self.content = self.rendered_content
  File "/opt/py3/lib/python3.6/site-packages/django/template/response.py", line 81, in rendered_content
    template = self.resolve_template(self.template_name)
  File "/opt/py3/lib/python3.6/site-packages/django/template/response.py", line 63, in resolve_template
    return select_template(template, using=self.using)
  File "/opt/py3/lib/python3.6/site-packages/django/template/loader.py", line 47, in select_template
    raise TemplateDoesNotExist(', '.join(template_name_list), chain=chain)
django.template.exceptions.TemplateDoesNotExist: mongo/mongo_list.html
2019-03-07 10:53:51 [log ERROR] Internal Server Error: /dbaudits/mongo-list
Traceback (most recent call last):
  File "/opt/py3/lib/python3.6/site-packages/django/core/handlers/exception.py", line 34, in inner
    response = get_response(request)
  File "/opt/py3/lib/python3.6/site-packages/django/core/handlers/base.py", line 156, in _get_response
    response = self.process_exception_by_middleware(e, request)
  File "/opt/py3/lib/python3.6/site-packages/django/core/handlers/base.py", line 154, in _get_response
    response = response.render()
  File "/opt/py3/lib/python3.6/site-packages/django/template/response.py", line 106, in render
    self.content = self.rendered_content
  File "/opt/py3/lib/python3.6/site-packages/django/template/response.py", line 81, in rendered_content
    template = self.resolve_template(self.template_name)
  File "/opt/py3/lib/python3.6/site-packages/django/template/response.py", line 63, in resolve_template
    return select_template(template, using=self.using)
  File "/opt/py3/lib/python3.6/site-packages/django/template/loader.py", line 47, in select_template
    raise TemplateDoesNotExist(', '.join(template_name_list), chain=chain)
django.template.exceptions.TemplateDoesNotExist: mongo/mongo_list.html
2019-03-07 10:53:54 [log ERROR] Internal Server Error: /dbaudits/mongo-list
Traceback (most recent call last):
  File "/opt/py3/lib/python3.6/site-packages/django/core/handlers/exception.py", line 34, in inner
    response = get_response(request)
  File "/opt/py3/lib/python3.6/site-packages/django/core/handlers/base.py", line 156, in _get_response
    response = self.process_exception_by_middleware(e, request)
  File "/opt/py3/lib/python3.6/site-packages/django/core/handlers/base.py", line 154, in _get_response
    response = response.render()
  File "/opt/py3/lib/python3.6/site-packages/django/template/response.py", line 106, in render
    self.content = self.rendered_content
  File "/opt/py3/lib/python3.6/site-packages/django/template/response.py", line 81, in rendered_content
    template = self.resolve_template(self.template_name)
  File "/opt/py3/lib/python3.6/site-packages/django/template/response.py", line 63, in resolve_template
    return select_template(template, using=self.using)
  File "/opt/py3/lib/python3.6/site-packages/django/template/loader.py", line 47, in select_template
    raise TemplateDoesNotExist(', '.join(template_name_list), chain=chain)
django.template.exceptions.TemplateDoesNotExist: mongo/mongo_list.html
2019-03-07 10:54:41 [log ERROR] Internal Server Error: /dbaudits/mongo-list
Traceback (most recent call last):
  File "/opt/py3/lib/python3.6/site-packages/django/core/handlers/exception.py", line 34, in inner
    response = get_response(request)
  File "/opt/py3/lib/python3.6/site-packages/django/core/handlers/base.py", line 156, in _get_response
    response = self.process_exception_by_middleware(e, request)
  File "/opt/py3/lib/python3.6/site-packages/django/core/handlers/base.py", line 154, in _get_response
    response = response.render()
  File "/opt/py3/lib/python3.6/site-packages/django/template/response.py", line 106, in render
    self.content = self.rendered_content
  File "/opt/py3/lib/python3.6/site-packages/django/template/response.py", line 81, in rendered_content
    template = self.resolve_template(self.template_name)
  File "/opt/py3/lib/python3.6/site-packages/django/template/response.py", line 63, in resolve_template
    return select_template(template, using=self.using)
  File "/opt/py3/lib/python3.6/site-packages/django/template/loader.py", line 47, in select_template
    raise TemplateDoesNotExist(', '.join(template_name_list), chain=chain)
django.template.exceptions.TemplateDoesNotExist: mongo/mongo_list.html
2019-03-07 10:54:43 [log ERROR] Internal Server Error: /dbaudits/mongo-list
Traceback (most recent call last):
  File "/opt/py3/lib/python3.6/site-packages/django/core/handlers/exception.py", line 34, in inner
    response = get_response(request)
  File "/opt/py3/lib/python3.6/site-packages/django/core/handlers/base.py", line 156, in _get_response
    response = self.process_exception_by_middleware(e, request)
  File "/opt/py3/lib/python3.6/site-packages/django/core/handlers/base.py", line 154, in _get_response
    response = response.render()
  File "/opt/py3/lib/python3.6/site-packages/django/template/response.py", line 106, in render
    self.content = self.rendered_content
  File "/opt/py3/lib/python3.6/site-packages/django/template/response.py", line 81, in rendered_content
    template = self.resolve_template(self.template_name)
  File "/opt/py3/lib/python3.6/site-packages/django/template/response.py", line 63, in resolve_template
    return select_template(template, using=self.using)
  File "/opt/py3/lib/python3.6/site-packages/django/template/loader.py", line 47, in select_template
    raise TemplateDoesNotExist(', '.join(template_name_list), chain=chain)
django.template.exceptions.TemplateDoesNotExist: mongo/mongo_list.html
2019-03-07 10:54:44 [log ERROR] Internal Server Error: /dbaudits/mongo-list
Traceback (most recent call last):
  File "/opt/py3/lib/python3.6/site-packages/django/core/handlers/exception.py", line 34, in inner
    response = get_response(request)
  File "/opt/py3/lib/python3.6/site-packages/django/core/handlers/base.py", line 156, in _get_response
    response = self.process_exception_by_middleware(e, request)
  File "/opt/py3/lib/python3.6/site-packages/django/core/handlers/base.py", line 154, in _get_response
    response = response.render()
  File "/opt/py3/lib/python3.6/site-packages/django/template/response.py", line 106, in render
    self.content = self.rendered_content
  File "/opt/py3/lib/python3.6/site-packages/django/template/response.py", line 81, in rendered_content
    template = self.resolve_template(self.template_name)
  File "/opt/py3/lib/python3.6/site-packages/django/template/response.py", line 63, in resolve_template
    return select_template(template, using=self.using)
  File "/opt/py3/lib/python3.6/site-packages/django/template/loader.py", line 47, in select_template
    raise TemplateDoesNotExist(', '.join(template_name_list), chain=chain)
django.template.exceptions.TemplateDoesNotExist: mongo/mongo_list.html
2019-03-07 10:54:46 [log ERROR] Internal Server Error: /dbaudits/mongo-list
Traceback (most recent call last):
  File "/opt/py3/lib/python3.6/site-packages/django/core/handlers/exception.py", line 34, in inner
    response = get_response(request)
  File "/opt/py3/lib/python3.6/site-packages/django/core/handlers/base.py", line 156, in _get_response
    response = self.process_exception_by_middleware(e, request)
  File "/opt/py3/lib/python3.6/site-packages/django/core/handlers/base.py", line 154, in _get_response
    response = response.render()
  File "/opt/py3/lib/python3.6/site-packages/django/template/response.py", line 106, in render
    self.content = self.rendered_content
  File "/opt/py3/lib/python3.6/site-packages/django/template/response.py", line 81, in rendered_content
    template = self.resolve_template(self.template_name)
  File "/opt/py3/lib/python3.6/site-packages/django/template/response.py", line 63, in resolve_template
    return select_template(template, using=self.using)
  File "/opt/py3/lib/python3.6/site-packages/django/template/loader.py", line 47, in select_template
    raise TemplateDoesNotExist(', '.join(template_name_list), chain=chain)
django.template.exceptions.TemplateDoesNotExist: mongo/mongo_list.html
2019-03-07 10:55:02 [log ERROR] Internal Server Error: /dbaudits/mongo-list
Traceback (most recent call last):
  File "/opt/py3/lib/python3.6/site-packages/django/core/handlers/exception.py", line 34, in inner
    response = get_response(request)
  File "/opt/py3/lib/python3.6/site-packages/django/core/handlers/base.py", line 156, in _get_response
    response = self.process_exception_by_middleware(e, request)
  File "/opt/py3/lib/python3.6/site-packages/django/core/handlers/base.py", line 154, in _get_response
    response = response.render()
  File "/opt/py3/lib/python3.6/site-packages/django/template/response.py", line 106, in render
    self.content = self.rendered_content
  File "/opt/py3/lib/python3.6/site-packages/django/template/response.py", line 81, in rendered_content
    template = self.resolve_template(self.template_name)
  File "/opt/py3/lib/python3.6/site-packages/django/template/response.py", line 63, in resolve_template
    return select_template(template, using=self.using)
  File "/opt/py3/lib/python3.6/site-packages/django/template/loader.py", line 47, in select_template
    raise TemplateDoesNotExist(', '.join(template_name_list), chain=chain)
django.template.exceptions.TemplateDoesNotExist: mongo/mongo_list.html
2019-03-07 10:55:03 [log ERROR] Internal Server Error: /dbaudits/mongo-list
Traceback (most recent call last):
  File "/opt/py3/lib/python3.6/site-packages/django/core/handlers/exception.py", line 34, in inner
    response = get_response(request)
  File "/opt/py3/lib/python3.6/site-packages/django/core/handlers/base.py", line 156, in _get_response
    response = self.process_exception_by_middleware(e, request)
  File "/opt/py3/lib/python3.6/site-packages/django/core/handlers/base.py", line 154, in _get_response
    response = response.render()
  File "/opt/py3/lib/python3.6/site-packages/django/template/response.py", line 106, in render
    self.content = self.rendered_content
  File "/opt/py3/lib/python3.6/site-packages/django/template/response.py", line 81, in rendered_content
    template = self.resolve_template(self.template_name)
  File "/opt/py3/lib/python3.6/site-packages/django/template/response.py", line 63, in resolve_template
    return select_template(template, using=self.using)
  File "/opt/py3/lib/python3.6/site-packages/django/template/loader.py", line 47, in select_template
    raise TemplateDoesNotExist(', '.join(template_name_list), chain=chain)
django.template.exceptions.TemplateDoesNotExist: mongo/mongo_list.html
2019-03-07 10:55:03 [log ERROR] Internal Server Error: /dbaudits/mongo-list
Traceback (most recent call last):
  File "/opt/py3/lib/python3.6/site-packages/django/core/handlers/exception.py", line 34, in inner
    response = get_response(request)
  File "/opt/py3/lib/python3.6/site-packages/django/core/handlers/base.py", line 156, in _get_response
    response = self.process_exception_by_middleware(e, request)
  File "/opt/py3/lib/python3.6/site-packages/django/core/handlers/base.py", line 154, in _get_response
    response = response.render()
  File "/opt/py3/lib/python3.6/site-packages/django/template/response.py", line 106, in render
    self.content = self.rendered_content
  File "/opt/py3/lib/python3.6/site-packages/django/template/response.py", line 81, in rendered_content
    template = self.resolve_template(self.template_name)
  File "/opt/py3/lib/python3.6/site-packages/django/template/response.py", line 63, in resolve_template
    return select_template(template, using=self.using)
  File "/opt/py3/lib/python3.6/site-packages/django/template/loader.py", line 47, in select_template
    raise TemplateDoesNotExist(', '.join(template_name_list), chain=chain)
django.template.exceptions.TemplateDoesNotExist: mongo/mongo_list.html
2019-03-07 10:55:04 [log ERROR] Internal Server Error: /dbaudits/mongo-list
Traceback (most recent call last):
  File "/opt/py3/lib/python3.6/site-packages/django/core/handlers/exception.py", line 34, in inner
    response = get_response(request)
  File "/opt/py3/lib/python3.6/site-packages/django/core/handlers/base.py", line 156, in _get_response
    response = self.process_exception_by_middleware(e, request)
  File "/opt/py3/lib/python3.6/site-packages/django/core/handlers/base.py", line 154, in _get_response
    response = response.render()
  File "/opt/py3/lib/python3.6/site-packages/django/template/response.py", line 106, in render
    self.content = self.rendered_content
  File "/opt/py3/lib/python3.6/site-packages/django/template/response.py", line 81, in rendered_content
    template = self.resolve_template(self.template_name)
  File "/opt/py3/lib/python3.6/site-packages/django/template/response.py", line 63, in resolve_template
    return select_template(template, using=self.using)
  File "/opt/py3/lib/python3.6/site-packages/django/template/loader.py", line 47, in select_template
    raise TemplateDoesNotExist(', '.join(template_name_list), chain=chain)
django.template.exceptions.TemplateDoesNotExist: mongo/mongo_list.html
2019-03-07 10:55:15 [log ERROR] Internal Server Error: /dbaudits/mongo-list
Traceback (most recent call last):
  File "/opt/py3/lib/python3.6/site-packages/django/core/handlers/exception.py", line 34, in inner
    response = get_response(request)
  File "/opt/py3/lib/python3.6/site-packages/django/core/handlers/base.py", line 156, in _get_response
    response = self.process_exception_by_middleware(e, request)
  File "/opt/py3/lib/python3.6/site-packages/django/core/handlers/base.py", line 154, in _get_response
    response = response.render()
  File "/opt/py3/lib/python3.6/site-packages/django/template/response.py", line 106, in render
    self.content = self.rendered_content
  File "/opt/py3/lib/python3.6/site-packages/django/template/response.py", line 81, in rendered_content
    template = self.resolve_template(self.template_name)
  File "/opt/py3/lib/python3.6/site-packages/django/template/response.py", line 63, in resolve_template
    return select_template(template, using=self.using)
  File "/opt/py3/lib/python3.6/site-packages/django/template/loader.py", line 47, in select_template
    raise TemplateDoesNotExist(', '.join(template_name_list), chain=chain)
django.template.exceptions.TemplateDoesNotExist: mongo/mongo_list.html
2019-03-07 11:39:58 [tasks ERROR] Sending mail error: [Errno -2] Name or service not known
2019-03-07 16:10:32 [log ERROR] Internal Server Error: /dbaudits/mongo-list
Traceback (most recent call last):
  File "/opt/py3/lib/python3.6/site-packages/django/core/handlers/exception.py", line 34, in inner
    response = get_response(request)
  File "/opt/py3/lib/python3.6/site-packages/django/core/handlers/base.py", line 156, in _get_response
    response = self.process_exception_by_middleware(e, request)
  File "/opt/py3/lib/python3.6/site-packages/django/core/handlers/base.py", line 154, in _get_response
    response = response.render()
  File "/opt/py3/lib/python3.6/site-packages/django/template/response.py", line 106, in render
    self.content = self.rendered_content
  File "/opt/py3/lib/python3.6/site-packages/django/template/response.py", line 83, in rendered_content
    content = template.render(context, self._request)
  File "/opt/py3/lib/python3.6/site-packages/django/template/backends/django.py", line 61, in render
    return self.template.render(context)
  File "/opt/py3/lib/python3.6/site-packages/django/template/base.py", line 171, in render
    return self._render(context)
  File "/opt/py3/lib/python3.6/site-packages/django/template/base.py", line 163, in _render
    return self.nodelist.render(context)
  File "/opt/py3/lib/python3.6/site-packages/django/template/base.py", line 937, in render
    bit = node.render_annotated(context)
  File "/opt/py3/lib/python3.6/site-packages/django/template/base.py", line 904, in render_annotated
    return self.render(context)
  File "/opt/py3/lib/python3.6/site-packages/django/template/loader_tags.py", line 150, in render
    return compiled_parent._render(context)
  File "/opt/py3/lib/python3.6/site-packages/django/template/base.py", line 163, in _render
    return self.nodelist.render(context)
  File "/opt/py3/lib/python3.6/site-packages/django/template/base.py", line 937, in render
    bit = node.render_annotated(context)
  File "/opt/py3/lib/python3.6/site-packages/django/template/base.py", line 904, in render_annotated
    return self.render(context)
  File "/opt/py3/lib/python3.6/site-packages/django/template/loader_tags.py", line 150, in render
    return compiled_parent._render(context)
  File "/opt/py3/lib/python3.6/site-packages/django/template/base.py", line 163, in _render
    return self.nodelist.render(context)
  File "/opt/py3/lib/python3.6/site-packages/django/template/base.py", line 937, in render
    bit = node.render_annotated(context)
  File "/opt/py3/lib/python3.6/site-packages/django/template/base.py", line 904, in render_annotated
    return self.render(context)
  File "/opt/py3/lib/python3.6/site-packages/django/template/loader_tags.py", line 62, in render
    result = block.nodelist.render(context)
  File "/opt/py3/lib/python3.6/site-packages/django/template/base.py", line 937, in render
    bit = node.render_annotated(context)
  File "/opt/py3/lib/python3.6/site-packages/django/template/base.py", line 904, in render_annotated
    return self.render(context)
  File "/opt/py3/lib/python3.6/site-packages/django/template/defaulttags.py", line 442, in render
    url = reverse(view_name, args=args, kwargs=kwargs, current_app=current_app)
  File "/opt/py3/lib/python3.6/site-packages/django/urls/base.py", line 90, in reverse
    return iri_to_uri(resolver._reverse_with_prefix(view, prefix, *args, **kwargs))
  File "/opt/py3/lib/python3.6/site-packages/django/urls/resolvers.py", line 622, in _reverse_with_prefix
    raise NoReverseMatch(msg)
django.urls.exceptions.NoReverseMatch: Reverse for 'mongosubmit' not found. 'mongosubmit' is not a valid view function or pattern name.
2019-03-07 16:16:00 [log ERROR] Internal Server Error: /dbaudits/mongo-list
Traceback (most recent call last):
  File "/opt/py3/lib/python3.6/site-packages/django/core/handlers/exception.py", line 34, in inner
    response = get_response(request)
  File "/opt/py3/lib/python3.6/site-packages/django/core/handlers/base.py", line 156, in _get_response
    response = self.process_exception_by_middleware(e, request)
  File "/opt/py3/lib/python3.6/site-packages/django/core/handlers/base.py", line 154, in _get_response
    response = response.render()
  File "/opt/py3/lib/python3.6/site-packages/django/template/response.py", line 106, in render
    self.content = self.rendered_content
  File "/opt/py3/lib/python3.6/site-packages/django/template/response.py", line 83, in rendered_content
    content = template.render(context, self._request)
  File "/opt/py3/lib/python3.6/site-packages/django/template/backends/django.py", line 61, in render
    return self.template.render(context)
  File "/opt/py3/lib/python3.6/site-packages/django/template/base.py", line 171, in render
    return self._render(context)
  File "/opt/py3/lib/python3.6/site-packages/django/template/base.py", line 163, in _render
    return self.nodelist.render(context)
  File "/opt/py3/lib/python3.6/site-packages/django/template/base.py", line 937, in render
    bit = node.render_annotated(context)
  File "/opt/py3/lib/python3.6/site-packages/django/template/base.py", line 904, in render_annotated
    return self.render(context)
  File "/opt/py3/lib/python3.6/site-packages/django/template/loader_tags.py", line 150, in render
    return compiled_parent._render(context)
  File "/opt/py3/lib/python3.6/site-packages/django/template/base.py", line 163, in _render
    return self.nodelist.render(context)
  File "/opt/py3/lib/python3.6/site-packages/django/template/base.py", line 937, in render
    bit = node.render_annotated(context)
  File "/opt/py3/lib/python3.6/site-packages/django/template/base.py", line 904, in render_annotated
    return self.render(context)
  File "/opt/py3/lib/python3.6/site-packages/django/template/loader_tags.py", line 150, in render
    return compiled_parent._render(context)
  File "/opt/py3/lib/python3.6/site-packages/django/template/base.py", line 163, in _render
    return self.nodelist.render(context)
  File "/opt/py3/lib/python3.6/site-packages/django/template/base.py", line 937, in render
    bit = node.render_annotated(context)
  File "/opt/py3/lib/python3.6/site-packages/django/template/base.py", line 904, in render_annotated
    return self.render(context)
  File "/opt/py3/lib/python3.6/site-packages/django/template/loader_tags.py", line 62, in render
    result = block.nodelist.render(context)
  File "/opt/py3/lib/python3.6/site-packages/django/template/base.py", line 937, in render
    bit = node.render_annotated(context)
  File "/opt/py3/lib/python3.6/site-packages/django/template/base.py", line 904, in render_annotated
    return self.render(context)
  File "/opt/py3/lib/python3.6/site-packages/django/template/defaulttags.py", line 442, in render
    url = reverse(view_name, args=args, kwargs=kwargs, current_app=current_app)
  File "/opt/py3/lib/python3.6/site-packages/django/urls/base.py", line 90, in reverse
    return iri_to_uri(resolver._reverse_with_prefix(view, prefix, *args, **kwargs))
  File "/opt/py3/lib/python3.6/site-packages/django/urls/resolvers.py", line 622, in _reverse_with_prefix
    raise NoReverseMatch(msg)
django.urls.exceptions.NoReverseMatch: Reverse for 'mongosubmit' not found. 'mongosubmit' is not a valid view function or pattern name.
2019-03-07 16:20:38 [log ERROR] Internal Server Error: /dbaudits/mongo-list
Traceback (most recent call last):
  File "/opt/py3/lib/python3.6/site-packages/django/core/handlers/exception.py", line 34, in inner
    response = get_response(request)
  File "/opt/py3/lib/python3.6/site-packages/django/core/handlers/base.py", line 156, in _get_response
    response = self.process_exception_by_middleware(e, request)
  File "/opt/py3/lib/python3.6/site-packages/django/core/handlers/base.py", line 154, in _get_response
    response = response.render()
  File "/opt/py3/lib/python3.6/site-packages/django/template/response.py", line 106, in render
    self.content = self.rendered_content
  File "/opt/py3/lib/python3.6/site-packages/django/template/response.py", line 83, in rendered_content
    content = template.render(context, self._request)
  File "/opt/py3/lib/python3.6/site-packages/django/template/backends/django.py", line 61, in render
    return self.template.render(context)
  File "/opt/py3/lib/python3.6/site-packages/django/template/base.py", line 171, in render
    return self._render(context)
  File "/opt/py3/lib/python3.6/site-packages/django/template/base.py", line 163, in _render
    return self.nodelist.render(context)
  File "/opt/py3/lib/python3.6/site-packages/django/template/base.py", line 937, in render
    bit = node.render_annotated(context)
  File "/opt/py3/lib/python3.6/site-packages/django/template/base.py", line 904, in render_annotated
    return self.render(context)
  File "/opt/py3/lib/python3.6/site-packages/django/template/loader_tags.py", line 150, in render
    return compiled_parent._render(context)
  File "/opt/py3/lib/python3.6/site-packages/django/template/base.py", line 163, in _render
    return self.nodelist.render(context)
  File "/opt/py3/lib/python3.6/site-packages/django/template/base.py", line 937, in render
    bit = node.render_annotated(context)
  File "/opt/py3/lib/python3.6/site-packages/django/template/base.py", line 904, in render_annotated
    return self.render(context)
  File "/opt/py3/lib/python3.6/site-packages/django/template/loader_tags.py", line 150, in render
    return compiled_parent._render(context)
  File "/opt/py3/lib/python3.6/site-packages/django/template/base.py", line 163, in _render
    return self.nodelist.render(context)
  File "/opt/py3/lib/python3.6/site-packages/django/template/base.py", line 937, in render
    bit = node.render_annotated(context)
  File "/opt/py3/lib/python3.6/site-packages/django/template/base.py", line 904, in render_annotated
    return self.render(context)
  File "/opt/py3/lib/python3.6/site-packages/django/template/loader_tags.py", line 62, in render
    result = block.nodelist.render(context)
  File "/opt/py3/lib/python3.6/site-packages/django/template/base.py", line 937, in render
    bit = node.render_annotated(context)
  File "/opt/py3/lib/python3.6/site-packages/django/template/base.py", line 904, in render_annotated
    return self.render(context)
  File "/opt/py3/lib/python3.6/site-packages/django/template/defaulttags.py", line 442, in render
    url = reverse(view_name, args=args, kwargs=kwargs, current_app=current_app)
  File "/opt/py3/lib/python3.6/site-packages/django/urls/base.py", line 90, in reverse
    return iri_to_uri(resolver._reverse_with_prefix(view, prefix, *args, **kwargs))
  File "/opt/py3/lib/python3.6/site-packages/django/urls/resolvers.py", line 622, in _reverse_with_prefix
    raise NoReverseMatch(msg)
django.urls.exceptions.NoReverseMatch: Reverse for 'mongosubmit' not found. 'mongosubmit' is not a valid view function or pattern name.
2019-03-07 16:20:49 [log ERROR] Internal Server Error: /dbaudits/mongo-list
Traceback (most recent call last):
  File "/opt/py3/lib/python3.6/site-packages/django/core/handlers/exception.py", line 34, in inner
    response = get_response(request)
  File "/opt/py3/lib/python3.6/site-packages/django/core/handlers/base.py", line 156, in _get_response
    response = self.process_exception_by_middleware(e, request)
  File "/opt/py3/lib/python3.6/site-packages/django/core/handlers/base.py", line 154, in _get_response
    response = response.render()
  File "/opt/py3/lib/python3.6/site-packages/django/template/response.py", line 106, in render
    self.content = self.rendered_content
  File "/opt/py3/lib/python3.6/site-packages/django/template/response.py", line 83, in rendered_content
    content = template.render(context, self._request)
  File "/opt/py3/lib/python3.6/site-packages/django/template/backends/django.py", line 61, in render
    return self.template.render(context)
  File "/opt/py3/lib/python3.6/site-packages/django/template/base.py", line 171, in render
    return self._render(context)
  File "/opt/py3/lib/python3.6/site-packages/django/template/base.py", line 163, in _render
    return self.nodelist.render(context)
  File "/opt/py3/lib/python3.6/site-packages/django/template/base.py", line 937, in render
    bit = node.render_annotated(context)
  File "/opt/py3/lib/python3.6/site-packages/django/template/base.py", line 904, in render_annotated
    return self.render(context)
  File "/opt/py3/lib/python3.6/site-packages/django/template/loader_tags.py", line 150, in render
    return compiled_parent._render(context)
  File "/opt/py3/lib/python3.6/site-packages/django/template/base.py", line 163, in _render
    return self.nodelist.render(context)
  File "/opt/py3/lib/python3.6/site-packages/django/template/base.py", line 937, in render
    bit = node.render_annotated(context)
  File "/opt/py3/lib/python3.6/site-packages/django/template/base.py", line 904, in render_annotated
    return self.render(context)
  File "/opt/py3/lib/python3.6/site-packages/django/template/loader_tags.py", line 150, in render
    return compiled_parent._render(context)
  File "/opt/py3/lib/python3.6/site-packages/django/template/base.py", line 163, in _render
    return self.nodelist.render(context)
  File "/opt/py3/lib/python3.6/site-packages/django/template/base.py", line 937, in render
    bit = node.render_annotated(context)
  File "/opt/py3/lib/python3.6/site-packages/django/template/base.py", line 904, in render_annotated
    return self.render(context)
  File "/opt/py3/lib/python3.6/site-packages/django/template/loader_tags.py", line 62, in render
    result = block.nodelist.render(context)
  File "/opt/py3/lib/python3.6/site-packages/django/template/base.py", line 937, in render
    bit = node.render_annotated(context)
  File "/opt/py3/lib/python3.6/site-packages/django/template/base.py", line 904, in render_annotated
    return self.render(context)
  File "/opt/py3/lib/python3.6/site-packages/django/template/defaulttags.py", line 442, in render
    url = reverse(view_name, args=args, kwargs=kwargs, current_app=current_app)
  File "/opt/py3/lib/python3.6/site-packages/django/urls/base.py", line 90, in reverse
    return iri_to_uri(resolver._reverse_with_prefix(view, prefix, *args, **kwargs))
  File "/opt/py3/lib/python3.6/site-packages/django/urls/resolvers.py", line 622, in _reverse_with_prefix
    raise NoReverseMatch(msg)
django.urls.exceptions.NoReverseMatch: Reverse for 'mongosubmit' not found. 'mongosubmit' is not a valid view function or pattern name.
2019-03-07 16:22:25 [log ERROR] Internal Server Error: /dbaudits/mongo-list
Traceback (most recent call last):
  File "/opt/py3/lib/python3.6/site-packages/django/core/handlers/exception.py", line 34, in inner
    response = get_response(request)
  File "/opt/py3/lib/python3.6/site-packages/django/core/handlers/base.py", line 156, in _get_response
    response = self.process_exception_by_middleware(e, request)
  File "/opt/py3/lib/python3.6/site-packages/django/core/handlers/base.py", line 154, in _get_response
    response = response.render()
  File "/opt/py3/lib/python3.6/site-packages/django/template/response.py", line 106, in render
    self.content = self.rendered_content
  File "/opt/py3/lib/python3.6/site-packages/django/template/response.py", line 83, in rendered_content
    content = template.render(context, self._request)
  File "/opt/py3/lib/python3.6/site-packages/django/template/backends/django.py", line 61, in render
    return self.template.render(context)
  File "/opt/py3/lib/python3.6/site-packages/django/template/base.py", line 171, in render
    return self._render(context)
  File "/opt/py3/lib/python3.6/site-packages/django/template/base.py", line 163, in _render
    return self.nodelist.render(context)
  File "/opt/py3/lib/python3.6/site-packages/django/template/base.py", line 937, in render
    bit = node.render_annotated(context)
  File "/opt/py3/lib/python3.6/site-packages/django/template/base.py", line 904, in render_annotated
    return self.render(context)
  File "/opt/py3/lib/python3.6/site-packages/django/template/loader_tags.py", line 150, in render
    return compiled_parent._render(context)
  File "/opt/py3/lib/python3.6/site-packages/django/template/base.py", line 163, in _render
    return self.nodelist.render(context)
  File "/opt/py3/lib/python3.6/site-packages/django/template/base.py", line 937, in render
    bit = node.render_annotated(context)
  File "/opt/py3/lib/python3.6/site-packages/django/template/base.py", line 904, in render_annotated
    return self.render(context)
  File "/opt/py3/lib/python3.6/site-packages/django/template/loader_tags.py", line 150, in render
    return compiled_parent._render(context)
  File "/opt/py3/lib/python3.6/site-packages/django/template/base.py", line 163, in _render
    return self.nodelist.render(context)
  File "/opt/py3/lib/python3.6/site-packages/django/template/base.py", line 937, in render
    bit = node.render_annotated(context)
  File "/opt/py3/lib/python3.6/site-packages/django/template/base.py", line 904, in render_annotated
    return self.render(context)
  File "/opt/py3/lib/python3.6/site-packages/django/template/loader_tags.py", line 62, in render
    result = block.nodelist.render(context)
  File "/opt/py3/lib/python3.6/site-packages/django/template/base.py", line 937, in render
    bit = node.render_annotated(context)
  File "/opt/py3/lib/python3.6/site-packages/django/template/base.py", line 904, in render_annotated
    return self.render(context)
  File "/opt/py3/lib/python3.6/site-packages/django/template/defaulttags.py", line 442, in render
    url = reverse(view_name, args=args, kwargs=kwargs, current_app=current_app)
  File "/opt/py3/lib/python3.6/site-packages/django/urls/base.py", line 90, in reverse
    return iri_to_uri(resolver._reverse_with_prefix(view, prefix, *args, **kwargs))
  File "/opt/py3/lib/python3.6/site-packages/django/urls/resolvers.py", line 622, in _reverse_with_prefix
    raise NoReverseMatch(msg)
django.urls.exceptions.NoReverseMatch: Reverse for 'mongo-submit' not found. 'mongo-submit' is not a valid view function or pattern name.
2019-03-07 16:22:29 [log ERROR] Internal Server Error: /dbaudits/mongo-list
Traceback (most recent call last):
  File "/opt/py3/lib/python3.6/site-packages/django/core/handlers/exception.py", line 34, in inner
    response = get_response(request)
  File "/opt/py3/lib/python3.6/site-packages/django/core/handlers/base.py", line 156, in _get_response
    response = self.process_exception_by_middleware(e, request)
  File "/opt/py3/lib/python3.6/site-packages/django/core/handlers/base.py", line 154, in _get_response
    response = response.render()
  File "/opt/py3/lib/python3.6/site-packages/django/template/response.py", line 106, in render
    self.content = self.rendered_content
  File "/opt/py3/lib/python3.6/site-packages/django/template/response.py", line 83, in rendered_content
    content = template.render(context, self._request)
  File "/opt/py3/lib/python3.6/site-packages/django/template/backends/django.py", line 61, in render
    return self.template.render(context)
  File "/opt/py3/lib/python3.6/site-packages/django/template/base.py", line 171, in render
    return self._render(context)
  File "/opt/py3/lib/python3.6/site-packages/django/template/base.py", line 163, in _render
    return self.nodelist.render(context)
  File "/opt/py3/lib/python3.6/site-packages/django/template/base.py", line 937, in render
    bit = node.render_annotated(context)
  File "/opt/py3/lib/python3.6/site-packages/django/template/base.py", line 904, in render_annotated
    return self.render(context)
  File "/opt/py3/lib/python3.6/site-packages/django/template/loader_tags.py", line 150, in render
    return compiled_parent._render(context)
  File "/opt/py3/lib/python3.6/site-packages/django/template/base.py", line 163, in _render
    return self.nodelist.render(context)
  File "/opt/py3/lib/python3.6/site-packages/django/template/base.py", line 937, in render
    bit = node.render_annotated(context)
  File "/opt/py3/lib/python3.6/site-packages/django/template/base.py", line 904, in render_annotated
    return self.render(context)
  File "/opt/py3/lib/python3.6/site-packages/django/template/loader_tags.py", line 150, in render
    return compiled_parent._render(context)
  File "/opt/py3/lib/python3.6/site-packages/django/template/base.py", line 163, in _render
    return self.nodelist.render(context)
  File "/opt/py3/lib/python3.6/site-packages/django/template/base.py", line 937, in render
    bit = node.render_annotated(context)
  File "/opt/py3/lib/python3.6/site-packages/django/template/base.py", line 904, in render_annotated
    return self.render(context)
  File "/opt/py3/lib/python3.6/site-packages/django/template/loader_tags.py", line 62, in render
    result = block.nodelist.render(context)
  File "/opt/py3/lib/python3.6/site-packages/django/template/base.py", line 937, in render
    bit = node.render_annotated(context)
  File "/opt/py3/lib/python3.6/site-packages/django/template/base.py", line 904, in render_annotated
    return self.render(context)
  File "/opt/py3/lib/python3.6/site-packages/django/template/defaulttags.py", line 442, in render
    url = reverse(view_name, args=args, kwargs=kwargs, current_app=current_app)
  File "/opt/py3/lib/python3.6/site-packages/django/urls/base.py", line 90, in reverse
    return iri_to_uri(resolver._reverse_with_prefix(view, prefix, *args, **kwargs))
  File "/opt/py3/lib/python3.6/site-packages/django/urls/resolvers.py", line 622, in _reverse_with_prefix
    raise NoReverseMatch(msg)
django.urls.exceptions.NoReverseMatch: Reverse for 'mongo-submit' not found. 'mongo-submit' is not a valid view function or pattern name.
2019-03-07 16:22:31 [log ERROR] Internal Server Error: /dbaudits/mongo-list
Traceback (most recent call last):
  File "/opt/py3/lib/python3.6/site-packages/django/core/handlers/exception.py", line 34, in inner
    response = get_response(request)
  File "/opt/py3/lib/python3.6/site-packages/django/core/handlers/base.py", line 156, in _get_response
    response = self.process_exception_by_middleware(e, request)
  File "/opt/py3/lib/python3.6/site-packages/django/core/handlers/base.py", line 154, in _get_response
    response = response.render()
  File "/opt/py3/lib/python3.6/site-packages/django/template/response.py", line 106, in render
    self.content = self.rendered_content
  File "/opt/py3/lib/python3.6/site-packages/django/template/response.py", line 83, in rendered_content
    content = template.render(context, self._request)
  File "/opt/py3/lib/python3.6/site-packages/django/template/backends/django.py", line 61, in render
    return self.template.render(context)
  File "/opt/py3/lib/python3.6/site-packages/django/template/base.py", line 171, in render
    return self._render(context)
  File "/opt/py3/lib/python3.6/site-packages/django/template/base.py", line 163, in _render
    return self.nodelist.render(context)
  File "/opt/py3/lib/python3.6/site-packages/django/template/base.py", line 937, in render
    bit = node.render_annotated(context)
  File "/opt/py3/lib/python3.6/site-packages/django/template/base.py", line 904, in render_annotated
    return self.render(context)
  File "/opt/py3/lib/python3.6/site-packages/django/template/loader_tags.py", line 150, in render
    return compiled_parent._render(context)
  File "/opt/py3/lib/python3.6/site-packages/django/template/base.py", line 163, in _render
    return self.nodelist.render(context)
  File "/opt/py3/lib/python3.6/site-packages/django/template/base.py", line 937, in render
    bit = node.render_annotated(context)
  File "/opt/py3/lib/python3.6/site-packages/django/template/base.py", line 904, in render_annotated
    return self.render(context)
  File "/opt/py3/lib/python3.6/site-packages/django/template/loader_tags.py", line 150, in render
    return compiled_parent._render(context)
  File "/opt/py3/lib/python3.6/site-packages/django/template/base.py", line 163, in _render
    return self.nodelist.render(context)
  File "/opt/py3/lib/python3.6/site-packages/django/template/base.py", line 937, in render
    bit = node.render_annotated(context)
  File "/opt/py3/lib/python3.6/site-packages/django/template/base.py", line 904, in render_annotated
    return self.render(context)
  File "/opt/py3/lib/python3.6/site-packages/django/template/loader_tags.py", line 62, in render
    result = block.nodelist.render(context)
  File "/opt/py3/lib/python3.6/site-packages/django/template/base.py", line 937, in render
    bit = node.render_annotated(context)
  File "/opt/py3/lib/python3.6/site-packages/django/template/base.py", line 904, in render_annotated
    return self.render(context)
  File "/opt/py3/lib/python3.6/site-packages/django/template/defaulttags.py", line 442, in render
    url = reverse(view_name, args=args, kwargs=kwargs, current_app=current_app)
  File "/opt/py3/lib/python3.6/site-packages/django/urls/base.py", line 90, in reverse
    return iri_to_uri(resolver._reverse_with_prefix(view, prefix, *args, **kwargs))
  File "/opt/py3/lib/python3.6/site-packages/django/urls/resolvers.py", line 622, in _reverse_with_prefix
    raise NoReverseMatch(msg)
django.urls.exceptions.NoReverseMatch: Reverse for 'mongo-submit' not found. 'mongo-submit' is not a valid view function or pattern name.
2019-03-07 16:29:12 [log ERROR] Internal Server Error: /dbaudits/mongo-list
Traceback (most recent call last):
  File "/opt/py3/lib/python3.6/site-packages/django/core/handlers/exception.py", line 34, in inner
    response = get_response(request)
  File "/opt/py3/lib/python3.6/site-packages/django/core/handlers/base.py", line 156, in _get_response
    response = self.process_exception_by_middleware(e, request)
  File "/opt/py3/lib/python3.6/site-packages/django/core/handlers/base.py", line 154, in _get_response
    response = response.render()
  File "/opt/py3/lib/python3.6/site-packages/django/template/response.py", line 106, in render
    self.content = self.rendered_content
  File "/opt/py3/lib/python3.6/site-packages/django/template/response.py", line 83, in rendered_content
    content = template.render(context, self._request)
  File "/opt/py3/lib/python3.6/site-packages/django/template/backends/django.py", line 61, in render
    return self.template.render(context)
  File "/opt/py3/lib/python3.6/site-packages/django/template/base.py", line 171, in render
    return self._render(context)
  File "/opt/py3/lib/python3.6/site-packages/django/template/base.py", line 163, in _render
    return self.nodelist.render(context)
  File "/opt/py3/lib/python3.6/site-packages/django/template/base.py", line 937, in render
    bit = node.render_annotated(context)
  File "/opt/py3/lib/python3.6/site-packages/django/template/base.py", line 904, in render_annotated
    return self.render(context)
  File "/opt/py3/lib/python3.6/site-packages/django/template/loader_tags.py", line 150, in render
    return compiled_parent._render(context)
  File "/opt/py3/lib/python3.6/site-packages/django/template/base.py", line 163, in _render
    return self.nodelist.render(context)
  File "/opt/py3/lib/python3.6/site-packages/django/template/base.py", line 937, in render
    bit = node.render_annotated(context)
  File "/opt/py3/lib/python3.6/site-packages/django/template/base.py", line 904, in render_annotated
    return self.render(context)
  File "/opt/py3/lib/python3.6/site-packages/django/template/loader_tags.py", line 150, in render
    return compiled_parent._render(context)
  File "/opt/py3/lib/python3.6/site-packages/django/template/base.py", line 163, in _render
    return self.nodelist.render(context)
  File "/opt/py3/lib/python3.6/site-packages/django/template/base.py", line 937, in render
    bit = node.render_annotated(context)
  File "/opt/py3/lib/python3.6/site-packages/django/template/base.py", line 904, in render_annotated
    return self.render(context)
  File "/opt/py3/lib/python3.6/site-packages/django/template/loader_tags.py", line 62, in render
    result = block.nodelist.render(context)
  File "/opt/py3/lib/python3.6/site-packages/django/template/base.py", line 937, in render
    bit = node.render_annotated(context)
  File "/opt/py3/lib/python3.6/site-packages/django/template/base.py", line 904, in render_annotated
    return self.render(context)
  File "/opt/py3/lib/python3.6/site-packages/django/template/defaulttags.py", line 442, in render
    url = reverse(view_name, args=args, kwargs=kwargs, current_app=current_app)
  File "/opt/py3/lib/python3.6/site-packages/django/urls/base.py", line 90, in reverse
    return iri_to_uri(resolver._reverse_with_prefix(view, prefix, *args, **kwargs))
  File "/opt/py3/lib/python3.6/site-packages/django/urls/resolvers.py", line 622, in _reverse_with_prefix
    raise NoReverseMatch(msg)
django.urls.exceptions.NoReverseMatch: Reverse for 'mongosubmit' not found. 'mongosubmit' is not a valid view function or pattern name.
2019-03-07 16:30:15 [log ERROR] Internal Server Error: /dbaudits/mongo-list
Traceback (most recent call last):
  File "/opt/py3/lib/python3.6/site-packages/django/core/handlers/exception.py", line 34, in inner
    response = get_response(request)
  File "/opt/py3/lib/python3.6/site-packages/django/core/handlers/base.py", line 156, in _get_response
    response = self.process_exception_by_middleware(e, request)
  File "/opt/py3/lib/python3.6/site-packages/django/core/handlers/base.py", line 154, in _get_response
    response = response.render()
  File "/opt/py3/lib/python3.6/site-packages/django/template/response.py", line 106, in render
    self.content = self.rendered_content
  File "/opt/py3/lib/python3.6/site-packages/django/template/response.py", line 83, in rendered_content
    content = template.render(context, self._request)
  File "/opt/py3/lib/python3.6/site-packages/django/template/backends/django.py", line 61, in render
    return self.template.render(context)
  File "/opt/py3/lib/python3.6/site-packages/django/template/base.py", line 171, in render
    return self._render(context)
  File "/opt/py3/lib/python3.6/site-packages/django/template/base.py", line 163, in _render
    return self.nodelist.render(context)
  File "/opt/py3/lib/python3.6/site-packages/django/template/base.py", line 937, in render
    bit = node.render_annotated(context)
  File "/opt/py3/lib/python3.6/site-packages/django/template/base.py", line 904, in render_annotated
    return self.render(context)
  File "/opt/py3/lib/python3.6/site-packages/django/template/loader_tags.py", line 150, in render
    return compiled_parent._render(context)
  File "/opt/py3/lib/python3.6/site-packages/django/template/base.py", line 163, in _render
    return self.nodelist.render(context)
  File "/opt/py3/lib/python3.6/site-packages/django/template/base.py", line 937, in render
    bit = node.render_annotated(context)
  File "/opt/py3/lib/python3.6/site-packages/django/template/base.py", line 904, in render_annotated
    return self.render(context)
  File "/opt/py3/lib/python3.6/site-packages/django/template/loader_tags.py", line 150, in render
    return compiled_parent._render(context)
  File "/opt/py3/lib/python3.6/site-packages/django/template/base.py", line 163, in _render
    return self.nodelist.render(context)
  File "/opt/py3/lib/python3.6/site-packages/django/template/base.py", line 937, in render
    bit = node.render_annotated(context)
  File "/opt/py3/lib/python3.6/site-packages/django/template/base.py", line 904, in render_annotated
    return self.render(context)
  File "/opt/py3/lib/python3.6/site-packages/django/template/loader_tags.py", line 62, in render
    result = block.nodelist.render(context)
  File "/opt/py3/lib/python3.6/site-packages/django/template/base.py", line 937, in render
    bit = node.render_annotated(context)
  File "/opt/py3/lib/python3.6/site-packages/django/template/base.py", line 904, in render_annotated
    return self.render(context)
  File "/opt/py3/lib/python3.6/site-packages/django/template/defaulttags.py", line 442, in render
    url = reverse(view_name, args=args, kwargs=kwargs, current_app=current_app)
  File "/opt/py3/lib/python3.6/site-packages/django/urls/base.py", line 90, in reverse
    return iri_to_uri(resolver._reverse_with_prefix(view, prefix, *args, **kwargs))
  File "/opt/py3/lib/python3.6/site-packages/django/urls/resolvers.py", line 622, in _reverse_with_prefix
    raise NoReverseMatch(msg)
django.urls.exceptions.NoReverseMatch: Reverse for 'mongo-submit' not found. 'mongo-submit' is not a valid view function or pattern name.
2019-03-07 16:30:54 [log ERROR] Internal Server Error: /dbaudits/mongo-list
Traceback (most recent call last):
  File "/opt/py3/lib/python3.6/site-packages/django/core/handlers/exception.py", line 34, in inner
    response = get_response(request)
  File "/opt/py3/lib/python3.6/site-packages/django/core/handlers/base.py", line 156, in _get_response
    response = self.process_exception_by_middleware(e, request)
  File "/opt/py3/lib/python3.6/site-packages/django/core/handlers/base.py", line 154, in _get_response
    response = response.render()
  File "/opt/py3/lib/python3.6/site-packages/django/template/response.py", line 106, in render
    self.content = self.rendered_content
  File "/opt/py3/lib/python3.6/site-packages/django/template/response.py", line 83, in rendered_content
    content = template.render(context, self._request)
  File "/opt/py3/lib/python3.6/site-packages/django/template/backends/django.py", line 61, in render
    return self.template.render(context)
  File "/opt/py3/lib/python3.6/site-packages/django/template/base.py", line 171, in render
    return self._render(context)
  File "/opt/py3/lib/python3.6/site-packages/django/template/base.py", line 163, in _render
    return self.nodelist.render(context)
  File "/opt/py3/lib/python3.6/site-packages/django/template/base.py", line 937, in render
    bit = node.render_annotated(context)
  File "/opt/py3/lib/python3.6/site-packages/django/template/base.py", line 904, in render_annotated
    return self.render(context)
  File "/opt/py3/lib/python3.6/site-packages/django/template/loader_tags.py", line 150, in render
    return compiled_parent._render(context)
  File "/opt/py3/lib/python3.6/site-packages/django/template/base.py", line 163, in _render
    return self.nodelist.render(context)
  File "/opt/py3/lib/python3.6/site-packages/django/template/base.py", line 937, in render
    bit = node.render_annotated(context)
  File "/opt/py3/lib/python3.6/site-packages/django/template/base.py", line 904, in render_annotated
    return self.render(context)
  File "/opt/py3/lib/python3.6/site-packages/django/template/loader_tags.py", line 150, in render
    return compiled_parent._render(context)
  File "/opt/py3/lib/python3.6/site-packages/django/template/base.py", line 163, in _render
    return self.nodelist.render(context)
  File "/opt/py3/lib/python3.6/site-packages/django/template/base.py", line 937, in render
    bit = node.render_annotated(context)
  File "/opt/py3/lib/python3.6/site-packages/django/template/base.py", line 904, in render_annotated
    return self.render(context)
  File "/opt/py3/lib/python3.6/site-packages/django/template/loader_tags.py", line 62, in render
    result = block.nodelist.render(context)
  File "/opt/py3/lib/python3.6/site-packages/django/template/base.py", line 937, in render
    bit = node.render_annotated(context)
  File "/opt/py3/lib/python3.6/site-packages/django/template/base.py", line 904, in render_annotated
    return self.render(context)
  File "/opt/py3/lib/python3.6/site-packages/django/template/defaulttags.py", line 442, in render
    url = reverse(view_name, args=args, kwargs=kwargs, current_app=current_app)
  File "/opt/py3/lib/python3.6/site-packages/django/urls/base.py", line 90, in reverse
    return iri_to_uri(resolver._reverse_with_prefix(view, prefix, *args, **kwargs))
  File "/opt/py3/lib/python3.6/site-packages/django/urls/resolvers.py", line 622, in _reverse_with_prefix
    raise NoReverseMatch(msg)
django.urls.exceptions.NoReverseMatch: Reverse for 'mongo-list' not found. 'mongo-list' is not a valid view function or pattern name.
2019-03-07 17:50:23 [log ERROR] Internal Server Error: /api/dbaudits/v1/mongosubmit/
Traceback (most recent call last):
  File "/opt/py3/lib/python3.6/site-packages/django/core/handlers/exception.py", line 34, in inner
    response = get_response(request)
  File "/opt/py3/lib/python3.6/site-packages/django/core/handlers/base.py", line 126, in _get_response
    response = self.process_exception_by_middleware(e, request)
  File "/opt/py3/lib/python3.6/site-packages/django/core/handlers/base.py", line 124, in _get_response
    response = wrapped_callback(request, *callback_args, **callback_kwargs)
  File "/usr/local/lib/python3.6/contextlib.py", line 53, in inner
    return func(*args, **kwds)
  File "/opt/py3/lib/python3.6/site-packages/django/views/decorators/csrf.py", line 54, in wrapped_view
    return view_func(*args, **kwargs)
  File "/opt/py3/lib/python3.6/site-packages/rest_framework/viewsets.py", line 103, in view
    return self.dispatch(request, *args, **kwargs)
  File "/opt/py3/lib/python3.6/site-packages/rest_framework/views.py", line 483, in dispatch
    response = self.handle_exception(exc)
  File "/opt/py3/lib/python3.6/site-packages/rest_framework/views.py", line 443, in handle_exception
    self.raise_uncaught_exception(exc)
  File "/opt/py3/lib/python3.6/site-packages/rest_framework/views.py", line 480, in dispatch
    response = handler(request, *args, **kwargs)
  File "/opt/py3/lib/python3.6/site-packages/rest_framework/mixins.py", line 48, in list
    return Response(serializer.data)
  File "/opt/py3/lib/python3.6/site-packages/rest_framework/serializers.py", line 765, in data
    ret = super(ListSerializer, self).data
  File "/opt/py3/lib/python3.6/site-packages/rest_framework/serializers.py", line 262, in data
    self._data = self.to_representation(self.instance)
  File "/opt/py3/lib/python3.6/site-packages/rest_framework/serializers.py", line 683, in to_representation
    self.child.to_representation(item) for item in iterable
  File "/opt/py3/lib/python3.6/site-packages/django/db/models/query.py", line 268, in __iter__
    self._fetch_all()
  File "/opt/py3/lib/python3.6/site-packages/django/db/models/query.py", line 1186, in _fetch_all
    self._result_cache = list(self._iterable_class(self))
  File "/opt/py3/lib/python3.6/site-packages/django/db/models/query.py", line 63, in __iter__
    for row in compiler.results_iter(results):
  File "/opt/py3/lib/python3.6/site-packages/django/db/models/sql/compiler.py", line 1009, in apply_converters
    value = converter(value, expression, connection)
  File "/opt/py3/lib/python3.6/site-packages/django/db/backends/mysql/operations.py", line 257, in convert_uuidfield_value
    value = uuid.UUID(value)
  File "/usr/local/lib/python3.6/uuid.py", line 140, in __init__
    raise ValueError('badly formed hexadecimal UUID string')
ValueError: badly formed hexadecimal UUID string
2019-03-07 17:50:26 [log ERROR] Internal Server Error: /api/dbaudits/v1/mongosubmit/
Traceback (most recent call last):
  File "/opt/py3/lib/python3.6/site-packages/django/core/handlers/exception.py", line 34, in inner
    response = get_response(request)
  File "/opt/py3/lib/python3.6/site-packages/django/core/handlers/base.py", line 126, in _get_response
    response = self.process_exception_by_middleware(e, request)
  File "/opt/py3/lib/python3.6/site-packages/django/core/handlers/base.py", line 124, in _get_response
    response = wrapped_callback(request, *callback_args, **callback_kwargs)
  File "/usr/local/lib/python3.6/contextlib.py", line 53, in inner
    return func(*args, **kwds)
  File "/opt/py3/lib/python3.6/site-packages/django/views/decorators/csrf.py", line 54, in wrapped_view
    return view_func(*args, **kwargs)
  File "/opt/py3/lib/python3.6/site-packages/rest_framework/viewsets.py", line 103, in view
    return self.dispatch(request, *args, **kwargs)
  File "/opt/py3/lib/python3.6/site-packages/rest_framework/views.py", line 483, in dispatch
    response = self.handle_exception(exc)
  File "/opt/py3/lib/python3.6/site-packages/rest_framework/views.py", line 443, in handle_exception
    self.raise_uncaught_exception(exc)
  File "/opt/py3/lib/python3.6/site-packages/rest_framework/views.py", line 480, in dispatch
    response = handler(request, *args, **kwargs)
  File "/opt/py3/lib/python3.6/site-packages/rest_framework/mixins.py", line 48, in list
    return Response(serializer.data)
  File "/opt/py3/lib/python3.6/site-packages/rest_framework/serializers.py", line 765, in data
    ret = super(ListSerializer, self).data
  File "/opt/py3/lib/python3.6/site-packages/rest_framework/serializers.py", line 262, in data
    self._data = self.to_representation(self.instance)
  File "/opt/py3/lib/python3.6/site-packages/rest_framework/serializers.py", line 683, in to_representation
    self.child.to_representation(item) for item in iterable
  File "/opt/py3/lib/python3.6/site-packages/django/db/models/query.py", line 268, in __iter__
    self._fetch_all()
  File "/opt/py3/lib/python3.6/site-packages/django/db/models/query.py", line 1186, in _fetch_all
    self._result_cache = list(self._iterable_class(self))
  File "/opt/py3/lib/python3.6/site-packages/django/db/models/query.py", line 63, in __iter__
    for row in compiler.results_iter(results):
  File "/opt/py3/lib/python3.6/site-packages/django/db/models/sql/compiler.py", line 1009, in apply_converters
    value = converter(value, expression, connection)
  File "/opt/py3/lib/python3.6/site-packages/django/db/backends/mysql/operations.py", line 257, in convert_uuidfield_value
    value = uuid.UUID(value)
  File "/usr/local/lib/python3.6/uuid.py", line 140, in __init__
    raise ValueError('badly formed hexadecimal UUID string')
ValueError: badly formed hexadecimal UUID string
2019-03-07 17:50:28 [log ERROR] Internal Server Error: /api/dbaudits/v1/mongosubmit/
Traceback (most recent call last):
  File "/opt/py3/lib/python3.6/site-packages/django/core/handlers/exception.py", line 34, in inner
    response = get_response(request)
  File "/opt/py3/lib/python3.6/site-packages/django/core/handlers/base.py", line 126, in _get_response
    response = self.process_exception_by_middleware(e, request)
  File "/opt/py3/lib/python3.6/site-packages/django/core/handlers/base.py", line 124, in _get_response
    response = wrapped_callback(request, *callback_args, **callback_kwargs)
  File "/usr/local/lib/python3.6/contextlib.py", line 53, in inner
    return func(*args, **kwds)
  File "/opt/py3/lib/python3.6/site-packages/django/views/decorators/csrf.py", line 54, in wrapped_view
    return view_func(*args, **kwargs)
  File "/opt/py3/lib/python3.6/site-packages/rest_framework/viewsets.py", line 103, in view
    return self.dispatch(request, *args, **kwargs)
  File "/opt/py3/lib/python3.6/site-packages/rest_framework/views.py", line 483, in dispatch
    response = self.handle_exception(exc)
  File "/opt/py3/lib/python3.6/site-packages/rest_framework/views.py", line 443, in handle_exception
    self.raise_uncaught_exception(exc)
  File "/opt/py3/lib/python3.6/site-packages/rest_framework/views.py", line 480, in dispatch
    response = handler(request, *args, **kwargs)
  File "/opt/py3/lib/python3.6/site-packages/rest_framework/mixins.py", line 48, in list
    return Response(serializer.data)
  File "/opt/py3/lib/python3.6/site-packages/rest_framework/serializers.py", line 765, in data
    ret = super(ListSerializer, self).data
  File "/opt/py3/lib/python3.6/site-packages/rest_framework/serializers.py", line 262, in data
    self._data = self.to_representation(self.instance)
  File "/opt/py3/lib/python3.6/site-packages/rest_framework/serializers.py", line 683, in to_representation
    self.child.to_representation(item) for item in iterable
  File "/opt/py3/lib/python3.6/site-packages/django/db/models/query.py", line 268, in __iter__
    self._fetch_all()
  File "/opt/py3/lib/python3.6/site-packages/django/db/models/query.py", line 1186, in _fetch_all
    self._result_cache = list(self._iterable_class(self))
  File "/opt/py3/lib/python3.6/site-packages/django/db/models/query.py", line 63, in __iter__
    for row in compiler.results_iter(results):
  File "/opt/py3/lib/python3.6/site-packages/django/db/models/sql/compiler.py", line 1009, in apply_converters
    value = converter(value, expression, connection)
  File "/opt/py3/lib/python3.6/site-packages/django/db/backends/mysql/operations.py", line 257, in convert_uuidfield_value
    value = uuid.UUID(value)
  File "/usr/local/lib/python3.6/uuid.py", line 140, in __init__
    raise ValueError('badly formed hexadecimal UUID string')
ValueError: badly formed hexadecimal UUID string
2019-03-08 13:33:20 [tasks ERROR] Sending mail error: [Errno -2] Name or service not known
2019-03-11 16:05:28 [log ERROR] Internal Server Error: /api/dbaudits/v1/mongosubmit/
Traceback (most recent call last):
  File "/opt/py3/lib/python3.6/site-packages/django/db/backends/utils.py", line 85, in _execute
    return self.cursor.execute(sql, params)
  File "/opt/py3/lib/python3.6/site-packages/django/db/backends/mysql/base.py", line 71, in execute
    return self.cursor.execute(query, args)
  File "/opt/py3/lib/python3.6/site-packages/MySQLdb/cursors.py", line 255, in execute
    self.errorhandler(self, exc, value)
  File "/opt/py3/lib/python3.6/site-packages/MySQLdb/connections.py", line 50, in defaulterrorhandler
    raise errorvalue
  File "/opt/py3/lib/python3.6/site-packages/MySQLdb/cursors.py", line 252, in execute
    res = self._query(query)
  File "/opt/py3/lib/python3.6/site-packages/MySQLdb/cursors.py", line 378, in _query
    db.query(q)
  File "/opt/py3/lib/python3.6/site-packages/MySQLdb/connections.py", line 280, in query
    _mysql.connection.query(self, query)
_mysql_exceptions.OperationalError: (1054, "Unknown column 'dbaudits_mongosubmit.status' in 'field list'")

The above exception was the direct cause of the following exception:

Traceback (most recent call last):
  File "/opt/py3/lib/python3.6/site-packages/django/core/handlers/exception.py", line 34, in inner
    response = get_response(request)
  File "/opt/py3/lib/python3.6/site-packages/django/core/handlers/base.py", line 126, in _get_response
    response = self.process_exception_by_middleware(e, request)
  File "/opt/py3/lib/python3.6/site-packages/django/core/handlers/base.py", line 124, in _get_response
    response = wrapped_callback(request, *callback_args, **callback_kwargs)
  File "/usr/local/lib/python3.6/contextlib.py", line 53, in inner
    return func(*args, **kwds)
  File "/opt/py3/lib/python3.6/site-packages/django/views/decorators/csrf.py", line 54, in wrapped_view
    return view_func(*args, **kwargs)
  File "/opt/py3/lib/python3.6/site-packages/rest_framework/viewsets.py", line 103, in view
    return self.dispatch(request, *args, **kwargs)
  File "/opt/py3/lib/python3.6/site-packages/rest_framework/views.py", line 483, in dispatch
    response = self.handle_exception(exc)
  File "/opt/py3/lib/python3.6/site-packages/rest_framework/views.py", line 443, in handle_exception
    self.raise_uncaught_exception(exc)
  File "/opt/py3/lib/python3.6/site-packages/rest_framework/views.py", line 480, in dispatch
    response = handler(request, *args, **kwargs)
  File "/opt/py3/lib/python3.6/site-packages/rest_framework/mixins.py", line 42, in list
    page = self.paginate_queryset(queryset)
  File "/opt/py3/lib/python3.6/site-packages/rest_framework/generics.py", line 173, in paginate_queryset
    return self.paginator.paginate_queryset(queryset, self.request, view=self)
  File "/opt/py3/lib/python3.6/site-packages/rest_framework/pagination.py", line 337, in paginate_queryset
    return list(queryset[self.offset:self.offset + self.limit])
  File "/opt/py3/lib/python3.6/site-packages/django/db/models/query.py", line 268, in __iter__
    self._fetch_all()
  File "/opt/py3/lib/python3.6/site-packages/django/db/models/query.py", line 1186, in _fetch_all
    self._result_cache = list(self._iterable_class(self))
  File "/opt/py3/lib/python3.6/site-packages/django/db/models/query.py", line 54, in __iter__
    results = compiler.execute_sql(chunked_fetch=self.chunked_fetch, chunk_size=self.chunk_size)
  File "/opt/py3/lib/python3.6/site-packages/django/db/models/sql/compiler.py", line 1065, in execute_sql
    cursor.execute(sql, params)
  File "/opt/py3/lib/python3.6/site-packages/django/db/backends/utils.py", line 68, in execute
    return self._execute_with_wrappers(sql, params, many=False, executor=self._execute)
  File "/opt/py3/lib/python3.6/site-packages/django/db/backends/utils.py", line 77, in _execute_with_wrappers
    return executor(sql, params, many, context)
  File "/opt/py3/lib/python3.6/site-packages/django/db/backends/utils.py", line 85, in _execute
    return self.cursor.execute(sql, params)
  File "/opt/py3/lib/python3.6/site-packages/django/db/utils.py", line 89, in __exit__
    raise dj_exc_value.with_traceback(traceback) from exc_value
  File "/opt/py3/lib/python3.6/site-packages/django/db/backends/utils.py", line 85, in _execute
    return self.cursor.execute(sql, params)
  File "/opt/py3/lib/python3.6/site-packages/django/db/backends/mysql/base.py", line 71, in execute
    return self.cursor.execute(query, args)
  File "/opt/py3/lib/python3.6/site-packages/MySQLdb/cursors.py", line 255, in execute
    self.errorhandler(self, exc, value)
  File "/opt/py3/lib/python3.6/site-packages/MySQLdb/connections.py", line 50, in defaulterrorhandler
    raise errorvalue
  File "/opt/py3/lib/python3.6/site-packages/MySQLdb/cursors.py", line 252, in execute
    res = self._query(query)
  File "/opt/py3/lib/python3.6/site-packages/MySQLdb/cursors.py", line 378, in _query
    db.query(q)
  File "/opt/py3/lib/python3.6/site-packages/MySQLdb/connections.py", line 280, in query
    _mysql.connection.query(self, query)
django.db.utils.OperationalError: (1054, "Unknown column 'dbaudits_mongosubmit.status' in 'field list'")
2019-03-12 17:35:26 [log ERROR] Internal Server Error: /api/dbaudits/v1/mongo-execute
Traceback (most recent call last):
  File "/opt/py3/lib/python3.6/site-packages/django/core/handlers/exception.py", line 34, in inner
    response = get_response(request)
  File "/opt/py3/lib/python3.6/site-packages/django/core/handlers/base.py", line 126, in _get_response
    response = self.process_exception_by_middleware(e, request)
  File "/opt/py3/lib/python3.6/site-packages/django/core/handlers/base.py", line 124, in _get_response
    response = wrapped_callback(request, *callback_args, **callback_kwargs)
  File "/usr/local/lib/python3.6/contextlib.py", line 53, in inner
    return func(*args, **kwds)
  File "/opt/py3/lib/python3.6/site-packages/django/views/generic/base.py", line 68, in view
    return self.dispatch(request, *args, **kwargs)
  File "/opt/jumpserver/apps/common/permissions.py", line 93, in dispatch
    return super().dispatch(request, *args, **kwargs)
  File "/opt/py3/lib/python3.6/site-packages/django/contrib/auth/mixins.py", line 109, in dispatch
    return super().dispatch(request, *args, **kwargs)
  File "/opt/py3/lib/python3.6/site-packages/django/views/generic/base.py", line 88, in dispatch
    return handler(request, *args, **kwargs)
  File "/opt/jumpserver/apps/dbaudits/api/mongo.py", line 46, in get
    deployjenkins.delay(env)
NameError: name 'deployjenkins' is not defined
2019-03-12 17:39:31 [log ERROR] Internal Server Error: /api/dbaudits/v1/mongo-execute
Traceback (most recent call last):
  File "/opt/py3/lib/python3.6/site-packages/django/core/handlers/exception.py", line 34, in inner
    response = get_response(request)
  File "/opt/py3/lib/python3.6/site-packages/django/core/handlers/base.py", line 126, in _get_response
    response = self.process_exception_by_middleware(e, request)
  File "/opt/py3/lib/python3.6/site-packages/django/core/handlers/base.py", line 124, in _get_response
    response = wrapped_callback(request, *callback_args, **callback_kwargs)
  File "/usr/local/lib/python3.6/contextlib.py", line 53, in inner
    return func(*args, **kwds)
  File "/opt/py3/lib/python3.6/site-packages/django/views/generic/base.py", line 68, in view
    return self.dispatch(request, *args, **kwargs)
  File "/opt/jumpserver/apps/common/permissions.py", line 93, in dispatch
    return super().dispatch(request, *args, **kwargs)
  File "/opt/py3/lib/python3.6/site-packages/django/contrib/auth/mixins.py", line 109, in dispatch
    return super().dispatch(request, *args, **kwargs)
  File "/opt/py3/lib/python3.6/site-packages/django/views/generic/base.py", line 88, in dispatch
    return handler(request, *args, **kwargs)
  File "/opt/jumpserver/apps/dbaudits/api/mongo.py", line 51, in get
    return HttpResponse(msg)
NameError: name 'HttpResponse' is not defined
